Workbook
Name _lst_r_地方财政预算表2015年全省汇总_10_科目编码名称: [1]_ESList!$A$1:$A$27
Name 专项收入年初预算数: #REF!
Name 专项收入全年预计数: #REF!
Name 专项收入年初预算数: #REF!
Name 专项收入全年预计数: #REF!
Name 专项收入年初预算数: #REF!
Name 专项收入全年预计数: #REF!
Name 专项收入年初预算数: #REF!
Name 专项收入全年预计数: #REF!
Name 专项收入年初预算数: #REF!
Name 专项收入全年预计数: #REF!
Name 专项收入年初预算数: #REF!
Name 专项收入全年预计数: #REF!
Name 专项收入年初预算数: #REF!
Name 专项收入全年预计数: #REF!
Name 专项收入年初预算数: #REF!
Name 专项收入全年预计数: #REF!
Name 专项收入年初预算数: #REF!
Name 专项收入全年预计数: #REF!
Name 专项收入年初预算数: #REF!
Name 专项收入全年预计数: #REF!
Name 专项收入年初预算数: #REF!
Name 专项收入全年预计数: #REF!
Name 专项收入年初预算数: #REF!
Name 专项收入全年预计数: #REF!
Name 专项收入年初预算数: #REF!
Name 专项收入全年预计数: #REF!
Name 专项收入年初预算数: #REF!
Name 专项收入全年预计数: #REF!
Name _lst_r_地方财政预算表2015年全省汇总_10_科目编码名称: [3]_ESList!$A$1:$A$27
Name 专项收入年初预算数: #REF!
Name 专项收入全年预计数: #REF!
Name _lst_r_地方财政预算表2015年全省汇总_10_科目编码名称: [3]_ESList!$A$1:$A$27
Name 专项收入年初预算数: #REF!
Name 专项收入全年预计数: #REF!
Name _lst_r_地方财政预算表2015年全省汇总_10_科目编码名称: [3]_ESList!$A$1:$A$27
Name 专项收入年初预算数: #REF!
Name 专项收入全年预计数: #REF!
Name _lst_r_地方财政预算表2015年全省汇总_10_科目编码名称: [4]_ESList!$A$1:$A$27
Name 专项收入年初预算数: #REF!
Name 专项收入全年预计数: #REF!
Name _lst_r_地方财政预算表2015年全省汇总_10_科目编码名称: [3]_ESList!$A$1:$A$27
Name 专项收入年初预算数: #REF!
Name 专项收入全年预计数: #REF!
Name _lst_r_地方财政预算表2015年全省汇总_10_科目编码名称: [3]_ESList!$A$1:$A$27
Name 专项收入年初预算数: #REF!
Name 专项收入全年预计数: #REF!
Name 专项收入年初预算数: #REF!
Name 专项收入全年预计数: #REF!
Name 专项收入年初预算数: #REF!
Name 专项收入全年预计数: #REF!
Name 专项收入年初预算数: #REF!
Name 专项收入全年预计数: #REF!
Name 专项收入年初预算数: #REF!
Name 专项收入全年预计数: #REF!
Name 专项收入年初预算数: #REF!
Name 专项收入全年预计数: #REF!
Name 专项收入年初预算数: #REF!
Name 专项收入全年预计数: #REF!
Name 专项收入年初预算数: #REF!

Sheet 封面
C1: 会议资料 妥善保存
B3: 丽 江 市
B4: =YEAR(B7)-1&"年地方财政预算执行情况和"&YEAR(B7)&"年地方财政预算（草案）" -> 2025年地方财政预算执行情况和2026年地方财政预算（草案） | E4: 3
E5: 8
B6: 丽江市财政局编制 | E6: 10
B7: 46037 | E7: 22
E8: 23
E9: 24
E10: 25
E11: 26
E12: 28
E13: 29
E14: 30
E15: 31
E16: 32
E17: 33
E18: 34
E19: 35
... E50: 94

Sheet 目录
A1: 目 录 | B1: 非打印区域（过程）
A3: =B3&"、"&C3&REPT(".",75-LENB(B3&"、"&C3&E3))&E3 -> 表一、2025年丽江市一般公共预算收支情况表..................................1 | B3: 表一 | C3: 2025年丽江市一般公共预算收支情况表 | D3: =LEN(C3) -> 19 | E3: 1
A4: =B4&"、"&C4&REPT(".",75-LENB(B4&"、"&C4&E4))&E4 -> 表二、2025年丽江市一般公共预算支出执行情况表..............................3 | B4: 表二 | C4: 2025年丽江市一般公共预算支出执行情况表 | D4: =LEN(C4) -> 21 | E4: 3
A5: =B5&"、"&C5&REPT(".",75-LENB(B5&"、"&C5&E5))&E5 -> 表三、2025年市本级一般公共预算收支情况表..................................8 | B5: 表三 | C5: 2025年市本级一般公共预算收支情况表 | D5: =LEN(C5) -> 19 | E5: 8
A6: =B6&"、"&C6&REPT(".",75-LENB(B6&"、"&C6&E6))&E6 -> 表四、2025年市本级一般公共预算支出执行情况表.............................10 | B6: 表四 | C6: 2025年市本级一般公共预算支出执行情况表 | D6: =LEN(C6) -> 21 | E6: 10
A7: =B7&"、"&C7&REPT(".",75-LENB(B7&"、"&C7&E7))&E7 -> 表五、2025年市本级预备费安排情况表.......................................22 | B7: 表五 | C7: 2025年市本级预备费安排情况表 | D7: =LEN(C7) -> 16 | E7: 22
A8: =B8&"、"&C8&REPT(".",75-LENB(B8&"、"&C8&E8))&E8 -> 表六、2025年丽江市政府性基金预算收入执行情况表...........................23 | B8: 表六 | C8: 2025年丽江市政府性基金预算收入执行情况表 | D8: =LEN(C8) -> 22 | E8: 23
A9: =B9&"、"&C9&REPT(".",75-LENB(B9&"、"&C9&E9))&E9 -> 表七、2025年丽江市政府性基金预算支出执行情况表...........................24 | B9: 表七 | C9: 2025年丽江市政府性基金预算支出执行情况表 | D9: =LEN(C9) -> 22 | E9: 24
A10: =B10&"、"&C10&REPT(".",75-LENB(B10&"、"&C10&E10))&E10 -> 表八、2025年市本级政府性基金预算收入执行情况表...........................25 | B10: 表八 | C10: 2025年市本级政府性基金预算收入执行情况表 | D10: =LEN(C10) -> 22 | E10: 25
A11: =B11&"、"&C11&REPT(".",75-LENB(B11&"、"&C11&E11))&E11 -> 表九、2025年市本级政府性基金预算支出执行情况表...........................26 | B11: 表九 | C11: 2025年市本级政府性基金预算支出执行情况表 | D11: =LEN(C11) -> 22 | E11: 26
A12: =B12&"、"&C12&REPT(".",75-LENB(B12&"、"&C12&E12))&E12 -> 表十、2025年丽江市国有资本经营预算收入执行情况表.........................28 | B12: 表十 | C12: 2025年丽江市国有资本经营预算收入执行情况表 | D12: =LEN(C12) -> 23 | E12: 28
A13: =B13&"、"&C13&REPT(".",75-LENB(B13&"、"&C13&E13))&E13 -> 表十一、2025年丽江市国有资本经营预算支出执行情况表.......................29 | B13: 表十一 | C13: 2025年丽江市国有资本经营预算支出执行情况表 | D13: =LEN(C13) -> 23 | E13: 29
A14: =B14&"、"&C14&REPT(".",75-LENB(B14&"、"&C14&E14))&E14 -> 表十二、2025年市本级国有资本经营预算收入执行情况表.......................30 | B14: 表十二 | C14: 2025年市本级国有资本经营预算收入执行情况表 | D14: =LEN(C14) -> 23 | E14: 30
... A20: =B20&"、"&C20&REPT(".",75-LENB(B20&"、"&C20&E20))&E20 -> 表十八、2025年市本级社会保险基金预算支出执行情况表.......................36 | B20: 表十八 | C20: 2025年市本级社会保险基金预算支出执行情况表 | D20: =LEN(C20) -> 23 | E20: 36
A21: =B21&" "&C21&REPT(".",75-LENB(B21&"、"&C21&E21))&E21 -> 表十九 2025年市本级社会保险基金预算结余执行情况表.......................37 | B21: 表十九 | C21: 2025年市本级社会保险基金预算结余执行情况表 | D21: =LEN(C21) -> 23 | E21: 37
A22: =B22&"、"&C22&REPT(".",75-LENB(B22&"、"&C22&E22))&E22 -> 表二十、2026年丽江市一般公共预算收支情况表...............................38 | B22: 表二十 | C22: 2026年丽江市一般公共预算收支情况表 | D22: =LEN(C22) -> 19 | E22: 38
A23: =B23&"、"&C23&REPT(".",75-LENB(B23&"、"&C23&E23))&E23 -> 表二十一、2026年丽江市一般公共预算支出情况表.............................40 | B23: 表二十一 | C23: 2026年丽江市一般公共预算支出情况表 | D23: =LEN(C23) -> 19 | E23: 40
A24: =B24&"、"&C24&REPT(".",75-LENB(B24&"、"&C24&E24))&E24 -> 表二十二、2026年市本级一般公共预算收支情况表.............................45 | B24: 表二十二 | C24: 2026年市本级一般公共预算收支情况表 | D24: =LEN(C24) -> 19 | E24: 45
A25: =B25&"、"&C25&REPT(".",75-LENB(B25&"、"&C25&E25))&E25 -> 表二十三、2026年市本级一般公共预算支出情况表.............................47 | B25: 表二十三 | C25: 2026年市本级一般公共预算支出情况表 | D25: =LEN(C25) -> 19 | E25: 47
A26: =B26&"、"&C26&REPT(".",75-LENB(B26&"、"&C26&E26))&E26 -> 表二十四、2026年丽江市市本级一般公共预算支出表(市对下转移支付项目).......61 | B26: 表二十四 | C26: 2026年丽江市市本级一般公共预算支出表(市对下转移支付项目) | D26: =LEN(C26) -> 31 | E26: 61
A27: =B27&"、"&C27&REPT(".",75-LENB(B27&"、"&C27&E27))&E27 -> 表二十五、2026年丽江市分地区税收返还和转移支付预算表.....................64 | B27: 表二十五 | C27: 2026年丽江市分地区税收返还和转移支付预算表 | D27: =LEN(C27) -> 23 | E27: 64
A28: =B28&"、"&C28&REPT(".",75-LENB(B28&"、"&C28&E28))&E28 -> 表二十六、2026年丽江市市本级一般公共预算政府预算经济分类表(基本支出).....65 | B28: 表二十六 | C28: 2026年丽江市市本级一般公共预算政府预算经济分类表(基本支出) | D28: =LEN(C28) -> 32 | E28: 65
A29: =B29&"、"&C29&REPT(".",75-LENB(B29&"、"&C29&E29))&E29 -> 表二十七、2026年丽江市市本级一般公共预算重点项目情况表...................66 | B29: 表二十七 | C29: 2026年丽江市市本级一般公共预算重点项目情况表 | D29: =LEN(C29) -> 24 | E29: 66
A30: =B30&"、"&C30&REPT(".",75-LENB(B30&"、"&C30&E30))&E30 -> 表二十八、2026年丽江市政府性基金预算收入情况表...........................67 | B30: 表二十八 | C30: 2026年丽江市政府性基金预算收入情况表 | D30: =LEN(C30) -> 20 | E30: 67
A31: =B31&"、"&C31&REPT(".",75-LENB(B31&"、"&C31&E31))&E31 -> 表二十九、2026年丽江市政府性基金预算支出情况表...........................68 | B31: 表二十九 | C31: 2026年丽江市政府性基金预算支出情况表 | D31: =LEN(C31) -> 20 | E31: 68
A32: =B32&"、"&C32&REPT(".",75-LENB(B32&"、"&C32&E32))&E32 -> 表三十、2026年市本级政府性基金预算收入情况表.............................69 | B32: 表三十 | C32: 2026年市本级政府性基金预算收入情况表 | D32: =LEN(C32) -> 20 | E32: 69
A33: =B33&"、"&C33&REPT(".",75-LENB(B33&"、"&C33&E33))&E33 -> 表三十一、2026年市本级政府性基金预算支出情况表...........................70 | B33: 表三十一 | C33: 2026年市本级政府性基金预算支出情况表 | D33: =LEN(C33) -> 20 | E33: 70
... A50: =B50&"、"&C50&REPT(".",75-LENB(B50&"、"&C50&E50))&E50 -> 表四十八、丽江市2025年地方政府债务限额分地区情况表.......................94 | B50: 表四十八 | C50: 丽江市2025年地方政府债务限额分地区情况表 | D50: =LEN(C50) -> 22 | E50: 94

Sheet 01-1 
B1: 2025年丽江市一般公共预算收支情况表
B2: 表一 | H2: 单位：万元
A3: 科目编码 | B3: 项目 | C3: 2024年决算数 | D3: 2025年 | G3: 比较
D4: 预算数 | E4: 3 | F4: 执行数 | G4: 比2024年决算数增长% | H4: 完成2025年预算数的% | I4: 打印
A5: 101 | B5: 一、税收收入 | C5: =SUM(C6:C20) -> 250422 | D5: =SUM(D6:D20) -> 292946 | E5: 8 | F5: =SUM(F6:F20) -> 288755 | G5: =IFERROR((F5-C5)/C5,"") -> 0.15307361 | H5: =IFERROR(F5/D5,"") -> 0.98569361 | I5: =IF(LEN(A5)=3,"是",IF(B5<>"",IF(SUM(C5:F5)<>0,"是","否"),"是")) -> 是
A6: 10101 | B6: 增值税 | C6: 114306 | D6: 126500 | E6: 10 | F6: 118670 | G6: =IFERROR((F6-C6)/C6,"") -> 0.038178223 | H6: =IFERROR(F6/D6,"") -> 0.93810277 | I6: =IF(LEN(A6)=3,"是",IF(B6<>"",IF(SUM(C6:F6)<>0,"是","否"),"是")) -> 是
A7: 10104 | B7: 企业所得税 | C7: 12462 | D7: 11520 | E7: 22 | F7: 11823 | G7: =IFERROR((F7-C7)/C7,"") -> -0.051275879 | H7: =IFERROR(F7/D7,"") -> 1.0263021 | I7: =IF(LEN(A7)=3,"是",IF(B7<>"",IF(SUM(C7:F7)<>0,"是","否"),"是")) -> 是
A8: 10106 | B8: 个人所得税 | C8: 4161 | D8: 3840 | E8: 23 | F8: 4342 | G8: =IFERROR((F8-C8)/C8,"") -> 0.043499159 | H8: =IFERROR(F8/D8,"") -> 1.1307292 | I8: =IF(LEN(A8)=3,"是",IF(B8<>"",IF(SUM(C8:F8)<>0,"是","否"),"是")) -> 是
A9: 10107 | B9: 资源税 | C9: 2752 | D9: 33246 | E9: 24 | F9: 28214 | G9: =IFERROR((F9-C9)/C9,"") -> 9.2521802 | H9: =IFERROR(F9/D9,"") -> 0.84864345 | I9: =IF(LEN(A9)=3,"是",IF(B9<>"",IF(SUM(C9:F9)<>0,"是","否"),"是")) -> 是
A10: 10109 | B10: 城市维护建设税 | C10: 14498 | D10: 15000 | E10: 25 | F10: 14184 | G10: =IFERROR((F10-C10)/C10,"") -> -0.02165816 | H10: =IFERROR(F10/D10,"") -> 0.9456 | I10: =IF(LEN(A10)=3,"是",IF(B10<>"",IF(SUM(C10:F10)<>0,"是","否"),"是")) -> 是
A11: 10110 | B11: 房产税 | C11: 14253 | D11: 14500 | E11: 26 | F11: 13926 | G11: =IFERROR((F11-C11)/C11,"") -> -0.022942538 | H11: =IFERROR(F11/D11,"") -> 0.96041379 | I11: =IF(LEN(A11)=3,"是",IF(B11<>"",IF(SUM(C11:F11)<>0,"是","否"),"是")) -> 是
A12: 10111 | B12: 印花税 | C12: 2994 | D12: 3200 | E12: 28 | F12: 2757 | G12: =IFERROR((F12-C12)/C12,"") -> -0.079158317 | H12: =IFERROR(F12/D12,"") -> 0.8615625 | I12: =IF(LEN(A12)=3,"是",IF(B12<>"",IF(SUM(C12:F12)<>0,"是","否"),"是")) -> 是
A13: 10112 | B13: 城镇土地使用税 | C13: 9799 | D13: 9800 | E13: 29 | F13: 10454 | G13: =IFERROR((F13-C13)/C13,"") -> 0.066843555 | H13: =IFERROR(F13/D13,"") -> 1.0667347 | I13: =IF(LEN(A13)=3,"是",IF(B13<>"",IF(SUM(C13:F13)<>0,"是","否"),"是")) -> 是
A14: 10113 | B14: 土地增值税 | C14: 13119 | D14: 13000 | E14: 30 | F14: 10748 | G14: =IFERROR((F14-C14)/C14,"") -> -0.18073024 | H14: =IFERROR(F14/D14,"") -> 0.82676923 | I14: =IF(LEN(A14)=3,"是",IF(B14<>"",IF(SUM(C14:F14)<>0,"是","否"),"是")) -> 是
A15: 10114 | B15: 车船税 | C15: 8014 | D15: 8000 | E15: 31 | F15: 8371 | G15: =IFERROR((F15-C15)/C15,"") -> 0.044547043 | H15: =IFERROR(F15/D15,"") -> 1.046375 | I15: =IF(LEN(A15)=3,"是",IF(B15<>"",IF(SUM(C15:F15)<>0,"是","否"),"是")) -> 是
A16: 10118 | B16: 耕地占用税 | C16: 14219 | D16: 14000 | E16: 32 | F16: 21925 | G16: =IFERROR((F16-C16)/C16,"") -> 0.54195091 | H16: =IFERROR(F16/D16,"") -> 1.5660714 | I16: =IF(LEN(A16)=3,"是",IF(B16<>"",IF(SUM(C16:F16)<>0,"是","否"),"是")) -> 是
A17: 10119 | B17: 契税 | C17: 17992 | D17: 18340 | E17: 33 | F17: 21104 | G17: =IFERROR((F17-C17)/C17,"") -> 0.17296576 | H17: =IFERROR(F17/D17,"") -> 1.1507088 | I17: =IF(LEN(A17)=3,"是",IF(B17<>"",IF(SUM(C17:F17)<>0,"是","否"),"是")) -> 是
... A19: 10121 | B19: 环境保护税 | C19: 1084 | D19: 1000 | E19: 35 | F19: 1259 | G19: =IFERROR((F19-C19)/C19,"") -> 0.16143911 | H19: =IFERROR(F19/D19,"") -> 1.259 | I19: =IF(LEN(A19)=3,"是",IF(B19<>"",IF(SUM(C19:F19)<>0,"是","否"),"是")) -> 是
A20: 10199 | B20: 其他税收收入 | C20: 40 | E20: 36 | F20: 169 | G20: =IFERROR((F20-C20)/C20,"") -> 3.225 | H20: =IFERROR(F20/D20,"") | I20: =IF(LEN(A20)=3,"是",IF(B20<>"",IF(SUM(C20:F20)<>0,"是","否"),"是")) -> 是
A21: 103 | B21: 二、非税收入 | C21: =SUM(C22:C29) -> 316281 | D21: =SUM(D22:D29) -> 302091 | E21: 37 | F21: =SUM(F22:F29) -> 279000 | G21: =IFERROR((F21-C21)/C21,"") -> -0.11787303 | H21: =IFERROR(F21/D21,"") -> 0.92356277 | I21: =IF(LEN(A21)=3,"是",IF(B21<>"",IF(SUM(C21:F21)<>0,"是","否"),"是")) -> 是
A22: 10302 | B22: 专项收入 | C22: 17795 | D22: 25653 | E22: 38 | F22: 14801 | G22: =IFERROR((F22-C22)/C22,"") -> -0.16824951 | H22: =IFERROR(F22/D22,"") -> 0.57696956 | I22: =IF(LEN(A22)=3,"是",IF(B22<>"",IF(SUM(C22:F22)<>0,"是","否"),"是")) -> 是
A23: 10304 | B23: 行政事业性收费收入 | C23: 46437 | D23: 43265 | E23: 40 | F23: 41771 | G23: =IFERROR((F23-C23)/C23,"") -> -0.10048022 | H23: =IFERROR(F23/D23,"") -> 0.96546862 | I23: =IF(LEN(A23)=3,"是",IF(B23<>"",IF(SUM(C23:F23)<>0,"是","否"),"是")) -> 是
A24: 10305 | B24: 罚没收入 | C24: 29964 | D24: 26859 | E24: 45 | F24: 19234 | G24: =IFERROR((F24-C24)/C24,"") -> -0.35809638 | H24: =IFERROR(F24/D24,"") -> 0.71611006 | I24: =IF(LEN(A24)=3,"是",IF(B24<>"",IF(SUM(C24:F24)<>0,"是","否"),"是")) -> 是
A25: 10306 | B25: 国有资本经营收入 | C25: 0 | E25: 47 | G25: =IFERROR((F25-C25)/C25,"") | H25: =IFERROR(F25/D25,"") | I25: =IF(LEN(A25)=3,"是",IF(B25<>"",IF(SUM(C25:F25)<>0,"是","否"),"是")) -> 是
A26: 10307 | B26: 国有资源（资产）有偿使用收入 | C26: 214227 | D26: 198693 | E26: 61 | F26: 194578 | G26: =IFERROR((F26-C26)/C26,"") -> -0.091720465 | H26: =IFERROR(F26/D26,"") -> 0.97928966 | I26: =IF(LEN(A26)=3,"是",IF(B26<>"",IF(SUM(C26:F26)<>0,"是","否"),"是")) -> 是
A27: 10308 | B27: 捐赠收入 | C27: 0 | E27: 64 | F27: 6 | G27: =IFERROR((F27-C27)/C27,"") | H27: =IFERROR(F27/D27,"") | I27: =IF(LEN(A27)=3,"是",IF(B27<>"",IF(SUM(C27:F27)<>0,"是","否"),"是")) -> 是
A28: 10309 | B28: 政府住房基金收入 | C28: 7847 | D28: 7621 | E28: 65 | F28: 8601 | G28: =IFERROR((F28-C28)/C28,"") -> 0.096087677 | H28: =IFERROR(F28/D28,"") -> 1.128592 | I28: =IF(LEN(A28)=3,"是",IF(B28<>"",IF(SUM(C28:F28)<>0,"是","否"),"是")) -> 是
A29: 10399 | B29: 其他收入 | C29: 11 | E29: 66 | F29: 9 | G29: =IFERROR((F29-C29)/C29,"") -> -0.18181818 | H29: =IFERROR(F29/D29,"") | I29: =IF(LEN(A29)=3,"是",IF(B29<>"",IF(SUM(C29:F29)<>0,"是","否"),"是")) -> 是
E30: 67 | G30: =IFERROR((F30-C30)/C30,"") | H30: =IFERROR(F30/D30,"") | I30: =IF(LEN(A30)=3,"是",IF(B30<>"",IF(SUM(C30:F30)<>0,"是","否"),"是")) -> 是
B31: 全市一般公共预算收入 | C31: =SUM(C21,C5) -> 566703 | D31: =SUM(D21,D5) -> 595037 | E31: 68 | F31: =SUM(F21,F5) -> 567755 | G31: =IFERROR((F31-C31)/C31,"") -> 0.0018563516 | H31: =IFERROR(F31/D31,"") -> 0.95415075 | I31: =IF(LEN(A31)=3,"是",IF(B31<>"",IF(SUM(C31:F31)<>0,"是","否"),"是")) -> 是
A32: 105 | B32: 地方政府一般债务收入 | C32: 180780 | D32: 192645 | E32: 69 | F32: 237945 | G32: =IFERROR((F32-C32)/C32,"") -> 0.31621308 | H32: =IFERROR(F32/D32,"") -> 1.2351476 | I32: =IF(LEN(A32)=3,"是",IF(B32<>"",IF(SUM(C32:F32)<>0,"是","否"),"是")) -> 是
A33: 110 | B33: 转移性收入 | C33: =SUM(C34:C40) -> 1326634 | D33: =SUM(D34:D40) -> 1316167 | E33: 70 | F33: =SUM(F34:F40) -> 1275374 | G33: =IFERROR((F33-C33)/C33,"") -> -0.038639142 | H33: =IFERROR(F33/D33,"") -> 0.96900621 | I33: =IF(LEN(A33)=3,"是",IF(B33<>"",IF(SUM(C33:F33)<>0,"是","否"),"是")) -> 是
A34: 11001 | B34: 返还性收入 | C34: 41410 | D34: 40300 | E34: 72 | F34: 44029 | G34: =IFERROR((F34-C34)/C34,"") -> 0.063245593 | H34: =IFERROR(F34/D34,"") -> 1.092531 | I34: =IF(LEN(A34)=3,"是",IF(B34<>"",IF(SUM(C34:F34)<>0,"是","否"),"是")) -> 是
B35: 一般性转移支付收入 | C35: 917106 | D35: 912417 | E35: 73 | F35: 997380 | G35: =IFERROR((F35-C35)/C35,"") -> 0.087529686 | H35: =IFERROR(F35/D35,"") -> 1.0931186 | I35: =IF(LEN(A35)=3,"是",IF(B35<>"",IF(SUM(C35:F35)<>0,"是","否"),"是")) -> 是
B36: 专项转移支付收入 | C36: 264430 | D36: 264427 | E36: 74 | F36: 144850 | G36: =IFERROR((F36-C36)/C36,"") -> -0.45221798 | H36: =IFERROR(F36/D36,"") -> 0.54778824 | I36: =IF(LEN(A36)=3,"是",IF(B36<>"",IF(SUM(C36:F36)<>0,"是","否"),"是")) -> 是
A37: 11008 | B37: 上年结余收入 | C37: 49215 | D37: 48090 | E37: 75 | F37: 48541 | G37: =IFERROR((F37-C37)/C37,"") -> -0.013695012 | H37: =IFERROR(F37/D37,"") -> 1.0093782 | I37: =IF(LEN(A37)=3,"是",IF(B37<>"",IF(SUM(C37:F37)<>0,"是","否"),"是")) -> 是
A38: 11009 | B38: 调入资金 | C38: 51974 | D38: 50933 | E38: 76 | F38: 34108 | G38: =IFERROR((F38-C38)/C38,"") -> -0.3437488 | H38: =IFERROR(F38/D38,"") -> 0.66966407 | I38: =IF(LEN(A38)=3,"是",IF(B38<>"",IF(SUM(C38:F38)<>0,"是","否"),"是")) -> 是
A39: 11015 | B39: 动用预算稳定调节基金 | C39: 2499 | E39: 77 | F39: 6330 | G39: =IFERROR((F39-C39)/C39,"") -> 1.5330132 | H39: =IFERROR(F39/D39,"") | I39: =IF(LEN(A39)=3,"是",IF(B39<>"",IF(SUM(C39:F39)<>0,"是","否"),"是")) -> 是
A40: 11021 | B40: 区域间转移性收入 | E40: 78 | F40: 136 | G40: =IFERROR((F40-C40)/C40,"") | H40: =IFERROR(F40/D40,"") | I40: =IF(LEN(A40)=3,"是",IF(B40<>"",IF(SUM(C40:F40)<>0,"是","否"),"是")) -> 是
B41: 各项收入合计 | C41: =SUM(C31:C32,C33) -> 2074117 | D41: =SUM(D31:D32,D33) -> 2103849 | E41: 79 | F41: =SUM(F31:F32,F33) -> 2081074 | G41: =IFERROR((F41-C41)/C41,"") -> 0.0033541984 | H41: =IFERROR(F41/D41,"") -> 0.9891746 | I41: =IF(LEN(A41)=3,"是",IF(B41<>"",IF(SUM(C41:F41)<>0,"是","否"),"是")) -> 是
...

Sheet 01-2
B1: 2025年丽江市一般公共预算收支情况表
B2: 表一 | H2: 单位：万元
A3: 科目编码 | B3: 项目 | C3: 2024年决算数 | D3: 2025年 | G3: 比较
D4: 预算数 | E4: 3 | F4: 执行数 | G4: 比2024年决算数增长% | H4: 完成2025年预算数的% | I4: 打印
A5: 201 | B5: 一、一般公共服务支出 | C5: 132245 | D5: 138494 | E5: 8 | F5: ='02'!E5 -> 149662 | G5: =IFERROR((F5-C5)/C5,"") -> 0.13170252 | H5: =IFERROR(F5/D5,"") -> 1.0806389 | I5: =IF(LEN(A5)=3,"是",IF(B5<>"",IF(SUM(C5:F5)<>0,"是","否"),"是")) -> 是
A6: 202 | B6: 二、外交支出 | C6: 0 | E6: 10 | F6: ='02'!E253 -> 0 | G6: =IFERROR((F6-C6)/C6,"") | H6: =IFERROR(F6/D6,"") | I6: =IF(LEN(A6)=3,"是",IF(B6<>"",IF(SUM(C6:F6)<>0,"是","否"),"是")) -> 是
A7: 203 | B7: 三、国防支出 | C7: 2090 | D7: 2103 | E7: 22 | F7: ='02'!E293 -> 2580 | G7: =IFERROR((F7-C7)/C7,"") -> 0.23444976 | H7: =IFERROR(F7/D7,"") -> 1.2268188 | I7: =IF(LEN(A7)=3,"是",IF(B7<>"",IF(SUM(C7:F7)<>0,"是","否"),"是")) -> 是
A8: 204 | B8: 四、公共安全支出 | C8: 71463 | D8: 72985 | E8: 23 | F8: ='02'!E312 -> 75378 | G8: =IFERROR((F8-C8)/C8,"") -> 0.054783594 | H8: =IFERROR(F8/D8,"") -> 1.0327876 | I8: =IF(LEN(A8)=3,"是",IF(B8<>"",IF(SUM(C8:F8)<>0,"是","否"),"是")) -> 是
A9: 205 | B9: 五、教育支出 | C9: 255457 | D9: 270715 | E9: 24 | F9: ='02'!E402 -> 272444 | G9: =IFERROR((F9-C9)/C9,"") -> 0.066496514 | H9: =IFERROR(F9/D9,"") -> 1.0063868 | I9: =IF(LEN(A9)=3,"是",IF(B9<>"",IF(SUM(C9:F9)<>0,"是","否"),"是")) -> 是
A10: 206 | B10: 六、科学技术支出 | C10: 4318 | D10: 4613 | E10: 25 | F10: ='02'!E454 -> 6843 | G10: =IFERROR((F10-C10)/C10,"") -> 0.58476146 | H10: =IFERROR(F10/D10,"") -> 1.4834164 | I10: =IF(LEN(A10)=3,"是",IF(B10<>"",IF(SUM(C10:F10)<>0,"是","否"),"是")) -> 是
A11: 207 | B11: 七、文化旅游体育与传媒支出 | C11: 24616 | D11: 25013 | E11: 26 | F11: ='02'!E510 -> 22563 | G11: =IFERROR((F11-C11)/C11,"") -> -0.08340104 | H11: =IFERROR(F11/D11,"") -> 0.90205093 | I11: =IF(LEN(A11)=3,"是",IF(B11<>"",IF(SUM(C11:F11)<>0,"是","否"),"是")) -> 是
A12: 208 | B12: 八、社会保障和就业支出 | C12: 290336 | D12: 295265 | E12: 28 | F12: ='02'!E567 -> 292685 | G12: =IFERROR((F12-C12)/C12,"") -> 0.008090626 | H12: =IFERROR(F12/D12,"") -> 0.99126209 | I12: =IF(LEN(A12)=3,"是",IF(B12<>"",IF(SUM(C12:F12)<>0,"是","否"),"是")) -> 是
A13: 210 | B13: 九、卫生健康支出 | C13: 196852 | D13: 201368 | E13: 29 | F13: ='02'!E697 -> 214985 | G13: =IFERROR((F13-C13)/C13,"") -> 0.092114888 | H13: =IFERROR(F13/D13,"") -> 1.0676225 | I13: =IF(LEN(A13)=3,"是",IF(B13<>"",IF(SUM(C13:F13)<>0,"是","否"),"是")) -> 是
A14: 211 | B14: 十、节能环保支出 | C14: 90624 | D14: 93216 | E14: 30 | F14: ='02'!E782 -> 109450 | G14: =IFERROR((F14-C14)/C14,"") -> 0.20773746 | H14: =IFERROR(F14/D14,"") -> 1.1741547 | I14: =IF(LEN(A14)=3,"是",IF(B14<>"",IF(SUM(C14:F14)<>0,"是","否"),"是")) -> 是
A15: 212 | B15: 十一、城乡社区支出 | C15: 70334 | D15: 68458 | E15: 31 | F15: ='02'!E854 -> 73971 | G15: =IFERROR((F15-C15)/C15,"") -> 0.05171041 | H15: =IFERROR(F15/D15,"") -> 1.0805311 | I15: =IF(LEN(A15)=3,"是",IF(B15<>"",IF(SUM(C15:F15)<>0,"是","否"),"是")) -> 是
A16: 213 | B16: 十二、农林水支出 | C16: 377451 | D16: 359895 | E16: 32 | F16: ='02'!E877 -> 239253 | G16: =IFERROR((F16-C16)/C16,"") -> -0.36613494 | H16: =IFERROR(F16/D16,"") -> 0.66478556 | I16: =IF(LEN(A16)=3,"是",IF(B16<>"",IF(SUM(C16:F16)<>0,"是","否"),"是")) -> 是
A17: 214 | B17: 十三、交通运输支出 | C17: 51669 | D17: 52184 | E17: 33 | F17: ='02'!E984 -> 66230 | G17: =IFERROR((F17-C17)/C17,"") -> 0.28181308 | H17: =IFERROR(F17/D17,"") -> 1.269163 | I17: =IF(LEN(A17)=3,"是",IF(B17<>"",IF(SUM(C17:F17)<>0,"是","否"),"是")) -> 是
A18: 215 | B18: 十四、资源勘探工业信息等支出 | C18: 75263 | D18: 69853 | E18: 34 | F18: ='02'!E1036 -> 76311 | G18: =IFERROR((F18-C18)/C18,"") -> 0.013924505 | H18: =IFERROR(F18/D18,"") -> 1.0924513 | I18: =IF(LEN(A18)=3,"是",IF(B18<>"",IF(SUM(C18:F18)<>0,"是","否"),"是")) -> 是
A19: 216 | B19: 十五、商业服务业等支出 | C19: 1873 | D19: 1912 | E19: 35 | F19: ='02'!E1100 -> 2905 | G19: =IFERROR((F19-C19)/C19,"") -> 0.55098772 | H19: =IFERROR(F19/D19,"") -> 1.5193515 | I19: =IF(LEN(A19)=3,"是",IF(B19<>"",IF(SUM(C19:F19)<>0,"是","否"),"是")) -> 是
A20: 217 | B20: 十六、金融支出 | C20: 644 | D20: 625 | E20: 36 | F20: ='02'!E1120 -> 1711 | G20: =IFERROR((F20-C20)/C20,"") -> 1.6568323 | H20: =IFERROR(F20/D20,"") -> 2.7376 | I20: =IF(LEN(A20)=3,"是",IF(B20<>"",IF(SUM(C20:F20)<>0,"是","否"),"是")) -> 是
A21: 219 | B21: 十七、援助其他地区支出 | C21: 0 | E21: 37 | F21: ='02'!E1150 -> 0 | G21: =IFERROR((F21-C21)/C21,"") | H21: =IFERROR(F21/D21,"") | I21: =IF(LEN(A21)=3,"是",IF(B21<>"",IF(SUM(C21:F21)<>0,"是","否"),"是")) -> 是
A22: 220 | B22: 十八、自然资源海洋气象等支出 | C22: 19061 | D22: 19853 | E22: 38 | F22: ='02'!E1160 -> 21460 | G22: =IFERROR((F22-C22)/C22,"") -> 0.12585908 | H22: =IFERROR(F22/D22,"") -> 1.0809449 | I22: =IF(LEN(A22)=3,"是",IF(B22<>"",IF(SUM(C22:F22)<>0,"是","否"),"是")) -> 是
A23: 221 | B23: 十九、住房保障支出 | C23: 65723 | D23: 67253 | E23: 40 | F23: ='02'!E1205 -> 61136 | G23: =IFERROR((F23-C23)/C23,"") -> -0.069792919 | H23: =IFERROR(F23/D23,"") -> 0.90904495 | I23: =IF(LEN(A23)=3,"是",IF(B23<>"",IF(SUM(C23:F23)<>0,"是","否"),"是")) -> 是
A24: 222 | B24: 二十、粮油物资储备支出 | C24: 2311 | D24: 2295 | E24: 45 | F24: ='02'!E1227 -> 2085 | G24: =IFERROR((F24-C24)/C24,"") -> -0.097793163 | H24: =IFERROR(F24/D24,"") -> 0.90849673 | I24: =IF(LEN(A24)=3,"是",IF(B24<>"",IF(SUM(C24:F24)<>0,"是","否"),"是")) -> 是
A25: 224 | B25: 二十一、灾害防治及应急管理支出 | C25: 27427 | D25: 26693 | E25: 47 | F25: ='02'!E1272 -> 21135 | G25: =IFERROR((F25-C25)/C25,"") -> -0.22940898 | H25: =IFERROR(F25/D25,"") -> 0.79178062 | I25: =IF(LEN(A25)=3,"是",IF(B25<>"",IF(SUM(C25:F25)<>0,"是","否"),"是")) -> 是
A26: 227 | B26: 二十二、预备费 | C26: 0 | D26: 18500 | E26: 61 | F26: ='02'!E1322 -> 0 | G26: =IFERROR((F26-C26)/C26,"") | H26: =IFERROR(F26/D26,"") -> 0 | I26: =IF(LEN(A26)=3,"是",IF(B26<>"",IF(SUM(C26:F26)<>0,"是","否"),"是")) -> 是
A27: 232 | B27: 二十三、债务付息支出 | C27: 48249 | D27: 45794 | E27: 64 | F27: ='02'!E1323 -> 46367 | G27: =IFERROR((F27-C27)/C27,"") -> -0.03900599 | H27: =IFERROR(F27/D27,"") -> 1.0125126 | I27: =IF(LEN(A27)=3,"是",IF(B27<>"",IF(SUM(C27:F27)<>0,"是","否"),"是")) -> 是
A28: 233 | B28: 二十四、债务发行费用支出 | C28: 187 | D28: 140 | E28: 65 | F28: ='02'!E1329 -> 238 | G28: =IFERROR((F28-C28)/C28,"") -> 0.27272727 | H28: =IFERROR(F28/D28,"") -> 1.7 | I28: =IF(LEN(A28)=3,"是",IF(B28<>"",IF(SUM(C28:F28)<>0,"是","否"),"是")) -> 是
A29: 229 | B29: 二十五、其他支出 | C29: 1883 | E29: 66 | F29: ='02'!E1331 -> 3839 | G29: =IFERROR((F29-C29)/C29,"") -> 1.0387679 | H29: =IFERROR(F29/D29,"") | I29: =IF(LEN(A29)=3,"是",IF(B29<>"",IF(SUM(C29:F29)<>0,"是","否"),"是")) -> 是
E30: 67 | G30: =IFERROR((F30-C30)/C30,"") | H30: =IFERROR(F30/D30,"") | I30: =IF(LEN(A30)=3,"是",IF(B30<>"",IF(SUM(C30:F30)<>0,"是","否"),"是")) -> 是
B31: 全市一般公共预算支出 | C31: =SUM(C5:C29) -> 1810076 | D31: =SUM(D5:D29) -> 1837227 | E31: 68 | F31: =SUM(F5:F29) -> 1763231 | G31: =IFERROR((F31-C31)/C31,"") -> -0.025880129 | H31: =IFERROR(F31/D31,"") -> 0.95972408 | I31: =IF(LEN(A31)=3,"是",IF(B31<>"",IF(SUM(C31:F31)<>0,"是","否"),"是")) -> 是
A32: 230 | B32: 转移性支出 | C32: =SUM(C33:C36) -> 40294 | D32: =SUM(D33:D36) -> 33869 | E32: 69 | F32: =SUM(F33:F36) -> 37977 | G32: =IFERROR((F32-C32)/C32,"") -> -0.057502358 | H32: =IFERROR(F32/D32,"") -> 1.1212909 | I32: =IF(LEN(A32)=3,"是",IF(B32<>"",IF(SUM(C32:F32)<>0,"是","否"),"是")) -> 是
A33: 23006 | B33: 上解支出 | C33: 33648 | D33: 33869 | E33: 70 | F33: 35218 | G33: =IFERROR((F33-C33)/C33,"") -> 0.046659534 | H33: =IFERROR(F33/D33,"") -> 1.0398299 | I33: =IF(LEN(A33)=3,"是",IF(B33<>"",IF(SUM(C33:F33)<>0,"是","否"),"是")) -> 是
A34: 23008 | B34: 调出资金 | C34: 3948 | E34: 72 | G34: =IFERROR((F34-C34)/C34,"") -> -1 | H34: =IFERROR(F34/D34,"") | I34: =IF(LEN(A34)=3,"是",IF(B34<>"",IF(SUM(C34:F34)<>0,"是","否"),"是")) -> 是
A35: 23015 | B35: 安排预算稳定调节基金 | C35: 2698 | E35: 73 | F35: 2759 | G35: =IFERROR((F35-C35)/C35,"") -> 0.02260934 | H35: =IFERROR(F35/D35,"") | I35: =IF(LEN(A35)=3,"是",IF(B35<>"",IF(SUM(C35:F35)<>0,"是","否"),"是")) -> 是
A36: 23016 | B36: 补充预算周转金 | C36: 0 | E36: 74 | G36: =IFERROR((F36-C36)/C36,"") | H36: =IFERROR(F36/D36,"") | I36: =IF(LEN(A36)=3,"是",IF(B36<>"",IF(SUM(C36:F36)<>0,"是","否"),"是")) -> 是
A37: 231 | B37: 地方政府一般债务还本支出 | C37: 175206 | D37: 214260 | E37: 75 | F37: 234021 | G37: =IFERROR((F37-C37)/C37,"") -> 0.33569056 | H37: =IFERROR(F37/D37,"") -> 1.0922291 | I37: =IF(LEN(A37)=3,"是",IF(B37<>"",IF(SUM(C37:F37)<>0,"是","否"),"是")) -> 是
A38: 23021 | B38: 区域间转移性支出 | E38: 76 | F38: 38 | G38: =IFERROR((F38-C38)/C38,"") | H38: =IFERROR(F38/D38,"") | I38: =IF(LEN(A38)=3,"是",IF(B38<>"",IF(SUM(C38:F38)<>0,"是","否"),"是")) -> 是
A39: 23009 | B39: 年终结转 | C39: 48541 | D39: 18493 | E39: 77 | F39: 45807 | G39: =IFERROR((F39-C39)/C39,"") -> -0.05632352 | H39: =IFERROR(F39/D39,"") -> 2.4769913 | I39: =IF(LEN(A39)=3,"是",IF(B39<>"",IF(SUM(C39:F39)<>0,"是","否"),"是")) -> 是
B40: 各项支出合计 | C40: =SUM(C31:C32,C37:C39) -> 2074117 | D40: =SUM(D31:D32,D37:D39) -> 2103849 | E40: 78 | F40: =SUM(F31:F32,F37:F39) -> 2081074 | G40: =IFERROR((F40-C40)/C40,"") -> 0.0033541984 | H40: =IFERROR(F40/D40,"") -> 0.9891746 | I40: =IF(LEN(A40)=3,"是",IF(B40<>"",IF(SUM(C40:F40)<>0,"是","否"),"是")) -> 是
...

Sheet 02
B1: 2025年丽江市一般公共预算支出执行情况表
B2: 表二 | G2: 单位：万元
B3: 项目 | C3: 2024年决算数 | D3: 2025年 | F3: 比较
A4: 科目编码 | D4: 预算数 | E4: 执行数 | F4: 比2024年决算数增长% | G4: 完成2025年预算数的% | H4: 打印 | I4: 类-款-项
A5: 201 | B5: 一、一般公共服务支出 | C5: =C6+C18+C27+C37+C48+C59+C70+C78+C87+C100+C109+C120+C132+C139+C147+C153+C160+C167+C174+C181+C188+C196+C202+C208+C215+C230+C237+C250 -> 132245 | D5: =D6+D18+D27+D37+D48+D59+D70+D78+D87+D100+D109+D120+D132+D139+D147+D153+D160+D167+D174+D181+D188+D196+D202+D208+D215+D230+D237+D250 -> 138494 | E5: =E6+E18+E27+E37+E48+E59+E70+E78+E87+E100+E109+E120+E132+E139+E147+E153+E160+E167+E174+E181+E188+E196+E202+E208+E215+E230+E237+E250 -> 149662 | F5: =IFERROR((E5-C5)/C5,"") -> 0.13170252 | G5: =IFERROR(E5/D5,"") -> 1.0806389 | H5: =IF(LEN(A5)=3,"是",IF(B5<>"",IF(SUM(C5:E5)<>0,"是","否"),"是")) -> 是 | I5: =IF(LEN(A5)=3,"类",IF(LEN(A5)=5,"款","项")) -> 类
A6: 20101 | B6: 人大事务 | C6: =SUM(C7:C17) -> 3063 | D6: =SUM(D7:D17) -> 3107 | E6: =SUM(E7:E17) -> 5903 | F6: =IFERROR((E6-C6)/C6,"") -> 0.92719556 | G6: =IFERROR(E6/D6,"") -> 1.8999034 | H6: =IF(LEN(A6)=3,"是",IF(B6<>"",IF(SUM(C6:E6)<>0,"是","否"),"是")) -> 是 | I6: =IF(LEN(A6)=3,"类",IF(LEN(A6)=5,"款","项")) -> 款
A7: 2010101 | B7: 行政运行 | C7: ='[2]2'!E7 -> 2225 | D7: 2256 | E7: 4990 | F7: =IFERROR((E7-C7)/C7,"") -> 1.2426966 | G7: =IFERROR(E7/D7,"") -> 2.2118794 | H7: =IF(LEN(A7)=3,"是",IF(B7<>"",IF(SUM(C7:E7)<>0,"是","否"),"是")) -> 是 | I7: =IF(LEN(A7)=3,"类",IF(LEN(A7)=5,"款","项")) -> 项
A8: 2010102 | B8: 一般行政管理事务 | C8: ='[2]2'!E8 -> 173 | D8: 182 | E8: 175 | F8: =IFERROR((E8-C8)/C8,"") -> 0.011560694 | G8: =IFERROR(E8/D8,"") -> 0.96153846 | H8: =IF(LEN(A8)=3,"是",IF(B8<>"",IF(SUM(C8:E8)<>0,"是","否"),"是")) -> 是 | I8: =IF(LEN(A8)=3,"类",IF(LEN(A8)=5,"款","项")) -> 项
A9: 2010103 | B9: 机关服务 | C9: ='[2]2'!E9 -> 57 | D9: 60 | E9: 54 | F9: =IFERROR((E9-C9)/C9,"") -> -0.052631579 | G9: =IFERROR(E9/D9,"") -> 0.9 | H9: =IF(LEN(A9)=3,"是",IF(B9<>"",IF(SUM(C9:E9)<>0,"是","否"),"是")) -> 是 | I9: =IF(LEN(A9)=3,"类",IF(LEN(A9)=5,"款","项")) -> 项
A10: 2010104 | B10: 人大会议 | C10: ='[2]2'!E10 -> 280 | D10: 285 | E10: 312 | F10: =IFERROR((E10-C10)/C10,"") -> 0.11428571 | G10: =IFERROR(E10/D10,"") -> 1.0947368 | H10: =IF(LEN(A10)=3,"是",IF(B10<>"",IF(SUM(C10:E10)<>0,"是","否"),"是")) -> 是 | I10: =IF(LEN(A10)=3,"类",IF(LEN(A10)=5,"款","项")) -> 项
A11: 2010105 | B11: 人大立法 | C11: ='[2]2'!E11 -> 1 | D11: 1 | E11: 4 | F11: =IFERROR((E11-C11)/C11,"") -> 3 | G11: =IFERROR(E11/D11,"") -> 4 | H11: =IF(LEN(A11)=3,"是",IF(B11<>"",IF(SUM(C11:E11)<>0,"是","否"),"是")) -> 是 | I11: =IF(LEN(A11)=3,"类",IF(LEN(A11)=5,"款","项")) -> 项
A12: 2010106 | B12: 人大监督 | C12: ='[2]2'!E12 -> 16 | D12: 17 | E12: 20 | F12: =IFERROR((E12-C12)/C12,"") -> 0.25 | G12: =IFERROR(E12/D12,"") -> 1.1764706 | H12: =IF(LEN(A12)=3,"是",IF(B12<>"",IF(SUM(C12:E12)<>0,"是","否"),"是")) -> 是 | I12: =IF(LEN(A12)=3,"类",IF(LEN(A12)=5,"款","项")) -> 项
A13: 2010107 | B13: 人大代表履职能力提升 | C13: ='[2]2'!E13 -> 112 | D13: 115 | E13: 94 | F13: =IFERROR((E13-C13)/C13,"") -> -0.16071429 | G13: =IFERROR(E13/D13,"") -> 0.8173913 | H13: =IF(LEN(A13)=3,"是",IF(B13<>"",IF(SUM(C13:E13)<>0,"是","否"),"是")) -> 是 | I13: =IF(LEN(A13)=3,"类",IF(LEN(A13)=5,"款","项")) -> 项
A14: 2010108 | B14: 代表工作 | C14: ='[2]2'!E14 -> 52 | D14: 55 | E14: 84 | F14: =IFERROR((E14-C14)/C14,"") -> 0.61538462 | G14: =IFERROR(E14/D14,"") -> 1.5272727 | H14: =IF(LEN(A14)=3,"是",IF(B14<>"",IF(SUM(C14:E14)<>0,"是","否"),"是")) -> 是 | I14: =IF(LEN(A14)=3,"类",IF(LEN(A14)=5,"款","项")) -> 项
A15: 2010109 | B15: 人大信访工作 | C15: ='[2]2'!E15 -> 0 | E15: 0 | F15: =IFERROR((E15-C15)/C15,"") | G15: =IFERROR(E15/D15,"") | H15: =IF(LEN(A15)=3,"是",IF(B15<>"",IF(SUM(C15:E15)<>0,"是","否"),"是")) -> 否 | I15: =IF(LEN(A15)=3,"类",IF(LEN(A15)=5,"款","项")) -> 项
A16: 2010150 | B16: 事业运行 | C16: ='[2]2'!E16 -> 34 | D16: 35 | E16: 0 | F16: =IFERROR((E16-C16)/C16,"") -> -1 | G16: =IFERROR(E16/D16,"") -> 0 | H16: =IF(LEN(A16)=3,"是",IF(B16<>"",IF(SUM(C16:E16)<>0,"是","否"),"是")) -> 是 | I16: =IF(LEN(A16)=3,"类",IF(LEN(A16)=5,"款","项")) -> 项
A17: 2010199 | B17: 其他人大事务支出 | C17: ='[2]2'!E17 -> 113 | D17: 101 | E17: 170 | F17: =IFERROR((E17-C17)/C17,"") -> 0.50442478 | G17: =IFERROR(E17/D17,"") -> 1.6831683 | H17: =IF(LEN(A17)=3,"是",IF(B17<>"",IF(SUM(C17:E17)<>0,"是","否"),"是")) -> 是 | I17: =IF(LEN(A17)=3,"类",IF(LEN(A17)=5,"款","项")) -> 项
A18: 20102 | B18: 政协事务 | C18: =SUM(C19:C26) -> 4957 | D18: =SUM(D19:D26) -> 4983 | E18: =SUM(E19:E26) -> 5289 | F18: =IFERROR((E18-C18)/C18,"") -> 0.066975994 | G18: =IFERROR(E18/D18,"") -> 1.0614088 | H18: =IF(LEN(A18)=3,"是",IF(B18<>"",IF(SUM(C18:E18)<>0,"是","否"),"是")) -> 是 | I18: =IF(LEN(A18)=3,"类",IF(LEN(A18)=5,"款","项")) -> 款
A19: 2010201 | B19: 行政运行 | C19: ='[2]2'!E19 -> 4464 | D19: 4485 | E19: 4791 | F19: =IFERROR((E19-C19)/C19,"") -> 0.073252688 | G19: =IFERROR(E19/D19,"") -> 1.0682274 | H19: =IF(LEN(A19)=3,"是",IF(B19<>"",IF(SUM(C19:E19)<>0,"是","否"),"是")) -> 是 | I19: =IF(LEN(A19)=3,"类",IF(LEN(A19)=5,"款","项")) -> 项
A20: 2010202 | B20: 一般行政管理事务 | C20: ='[2]2'!E20 -> 159 | D20: 162 | E20: 110 | F20: =IFERROR((E20-C20)/C20,"") -> -0.3081761 | G20: =IFERROR(E20/D20,"") -> 0.67901235 | H20: =IF(LEN(A20)=3,"是",IF(B20<>"",IF(SUM(C20:E20)<>0,"是","否"),"是")) -> 是 | I20: =IF(LEN(A20)=3,"类",IF(LEN(A20)=5,"款","项")) -> 项
A21: 2010203 | B21: 机关服务 | C21: ='[2]2'!E21 -> 0 | E21: 0 | F21: =IFERROR((E21-C21)/C21,"") | G21: =IFERROR(E21/D21,"") | H21: =IF(LEN(A21)=3,"是",IF(B21<>"",IF(SUM(C21:E21)<>0,"是","否"),"是")) -> 否 | I21: =IF(LEN(A21)=3,"类",IF(LEN(A21)=5,"款","项")) -> 项
A22: 2010204 | B22: 政协会议 | C22: ='[2]2'!E22 -> 172 | D22: 179 | E22: 137 | F22: =IFERROR((E22-C22)/C22,"") -> -0.20348837 | G22: =IFERROR(E22/D22,"") -> 0.76536313 | H22: =IF(LEN(A22)=3,"是",IF(B22<>"",IF(SUM(C22:E22)<>0,"是","否"),"是")) -> 是 | I22: =IF(LEN(A22)=3,"类",IF(LEN(A22)=5,"款","项")) -> 项
A23: 2010205 | B23: 委员视察 | C23: ='[2]2'!E23 -> 23 | D23: 25 | E23: 12 | F23: =IFERROR((E23-C23)/C23,"") -> -0.47826087 | G23: =IFERROR(E23/D23,"") -> 0.48 | H23: =IF(LEN(A23)=3,"是",IF(B23<>"",IF(SUM(C23:E23)<>0,"是","否"),"是")) -> 是 | I23: =IF(LEN(A23)=3,"类",IF(LEN(A23)=5,"款","项")) -> 项
A24: 2010206 | B24: 参政议政 | C24: ='[2]2'!E24 -> 19 | D24: 21 | E24: 14 | F24: =IFERROR((E24-C24)/C24,"") -> -0.26315789 | G24: =IFERROR(E24/D24,"") -> 0.66666667 | H24: =IF(LEN(A24)=3,"是",IF(B24<>"",IF(SUM(C24:E24)<>0,"是","否"),"是")) -> 是 | I24: =IF(LEN(A24)=3,"类",IF(LEN(A24)=5,"款","项")) -> 项
A25: 2010250 | B25: 事业运行 | C25: ='[2]2'!E25 -> 0 | E25: 0 | F25: =IFERROR((E25-C25)/C25,"") | G25: =IFERROR(E25/D25,"") | H25: =IF(LEN(A25)=3,"是",IF(B25<>"",IF(SUM(C25:E25)<>0,"是","否"),"是")) -> 否 | I25: =IF(LEN(A25)=3,"类",IF(LEN(A25)=5,"款","项")) -> 项
A26: 2010299 | B26: 其他政协事务支出 | C26: ='[2]2'!E26 -> 120 | D26: 111 | E26: 225 | F26: =IFERROR((E26-C26)/C26,"") -> 0.875 | G26: =IFERROR(E26/D26,"") -> 2.027027 | H26: =IF(LEN(A26)=3,"是",IF(B26<>"",IF(SUM(C26:E26)<>0,"是","否"),"是")) -> 是 | I26: =IF(LEN(A26)=3,"类",IF(LEN(A26)=5,"款","项")) -> 项
A27: 20103 | B27: 政府办公厅(室)及相关机构事务 | C27: =SUM(C28:C36) -> 47212 | D27: =SUM(D28:D36) -> 46455 | E27: =SUM(E28:E36) -> 53527 | F27: =IFERROR((E27-C27)/C27,"") -> 0.13375837 | G27: =IFERROR(E27/D27,"") -> 1.1522333 | H27: =IF(LEN(A27)=3,"是",IF(B27<>"",IF(SUM(C27:E27)<>0,"是","否"),"是")) -> 是 | I27: =IF(LEN(A27)=3,"类",IF(LEN(A27)=5,"款","项")) -> 款
A28: 2010301 | B28: 行政运行 | C28: ='[2]2'!E28 -> 30603 | D28: 30859 | E28: 32143 | F28: =IFERROR((E28-C28)/C28,"") -> 0.050321864 | G28: =IFERROR(E28/D28,"") -> 1.0416086 | H28: =IF(LEN(A28)=3,"是",IF(B28<>"",IF(SUM(C28:E28)<>0,"是","否"),"是")) -> 是 | I28: =IF(LEN(A28)=3,"类",IF(LEN(A28)=5,"款","项")) -> 项
A29: 2010302 | B29: 一般行政管理事务 | C29: ='[2]2'!E29 -> 1499 | D29: 1523 | E29: 1854 | F29: =IFERROR((E29-C29)/C29,"") -> 0.23682455 | G29: =IFERROR(E29/D29,"") -> 1.2173342 | H29: =IF(LEN(A29)=3,"是",IF(B29<>"",IF(SUM(C29:E29)<>0,"是","否"),"是")) -> 是 | I29: =IF(LEN(A29)=3,"类",IF(LEN(A29)=5,"款","项")) -> 项
A30: 2010303 | B30: 机关服务 | C30: ='[2]2'!E30 -> 825 | D30: 832 | E30: 730 | F30: =IFERROR((E30-C30)/C30,"") -> -0.11515152 | G30: =IFERROR(E30/D30,"") -> 0.87740385 | H30: =IF(LEN(A30)=3,"是",IF(B30<>"",IF(SUM(C30:E30)<>0,"是","否"),"是")) -> 是 | I30: =IF(LEN(A30)=3,"类",IF(LEN(A30)=5,"款","项")) -> 项
A31: 2010304 | B31: 专项服务 | C31: ='[2]2'!E31 -> 2 | D31: 0 | E31: 2 | F31: =IFERROR((E31-C31)/C31,"") -> 0 | G31: =IFERROR(E31/D31,"") | H31: =IF(LEN(A31)=3,"是",IF(B31<>"",IF(SUM(C31:E31)<>0,"是","否"),"是")) -> 是 | I31: =IF(LEN(A31)=3,"类",IF(LEN(A31)=5,"款","项")) -> 项
A32: 2010305 | B32: 专项业务及机关事务管理 | C32: ='[2]2'!E32 -> 18 | D32: 19 | E32: 9 | F32: =IFERROR((E32-C32)/C32,"") -> -0.5 | G32: =IFERROR(E32/D32,"") -> 0.47368421 | H32: =IF(LEN(A32)=3,"是",IF(B32<>"",IF(SUM(C32:E32)<>0,"是","否"),"是")) -> 是 | I32: =IF(LEN(A32)=3,"类",IF(LEN(A32)=5,"款","项")) -> 项
A33: 2010306 | B33: 政务公开审批 | C33: ='[2]2'!E33 -> 0 | E33: 0 | F33: =IFERROR((E33-C33)/C33,"") | G33: =IFERROR(E33/D33,"") | H33: =IF(LEN(A33)=3,"是",IF(B33<>"",IF(SUM(C33:E33)<>0,"是","否"),"是")) -> 否 | I33: =IF(LEN(A33)=3,"类",IF(LEN(A33)=5,"款","项")) -> 项
A34: 2010309 | B34: 参事事务 | C34: ='[2]2'!E34 -> 15 | D34: 16 | E34: 9 | F34: =IFERROR((E34-C34)/C34,"") -> -0.4 | G34: =IFERROR(E34/D34,"") -> 0.5625 | H34: =IF(LEN(A34)=3,"是",IF(B34<>"",IF(SUM(C34:E34)<>0,"是","否"),"是")) -> 是 | I34: =IF(LEN(A34)=3,"类",IF(LEN(A34)=5,"款","项")) -> 项
A35: 2010350 | B35: 事业运行 | C35: ='[2]2'!E35 -> 8879 | D35: 8921 | E35: 17719 | F35: =IFERROR((E35-C35)/C35,"") -> 0.99560761 | G35: =IFERROR(E35/D35,"") -> 1.9862123 | H35: =IF(LEN(A35)=3,"是",IF(B35<>"",IF(SUM(C35:E35)<>0,"是","否"),"是")) -> 是 | I35: =IF(LEN(A35)=3,"类",IF(LEN(A35)=5,"款","项")) -> 项
A36: 2010399 | B36: 其他政府办公厅（室）及相关机构事务支出 | C36: ='[2]2'!E36 -> 5371 | D36: 4285 | E36: 1061 | F36: =IFERROR((E36-C36)/C36,"") -> -0.80245764 | G36: =IFERROR(E36/D36,"") -> 0.24760793 | H36: =IF(LEN(A36)=3,"是",IF(B36<>"",IF(SUM(C36:E36)<>0,"是","否"),"是")) -> 是 | I36: =IF(LEN(A36)=3,"类",IF(LEN(A36)=5,"款","项")) -> 项
A37: 20104 | B37: 发展与改革事务 | C37: =SUM(C38:C47) -> 5400 | D37: =SUM(D38:D47) -> 5395 | E37: =SUM(E38:E47) -> 7745 | F37: =IFERROR((E37-C37)/C37,"") -> 0.43425926 | G37: =IFERROR(E37/D37,"") -> 1.4355885 | H37: =IF(LEN(A37)=3,"是",IF(B37<>"",IF(SUM(C37:E37)<>0,"是","否"),"是")) -> 是 | I37: =IF(LEN(A37)=3,"类",IF(LEN(A37)=5,"款","项")) -> 款
A38: 2010401 | B38: 行政运行 | C38: ='[2]2'!E38 -> 3174 | D38: 3195 | E38: 3194 | F38: =IFERROR((E38-C38)/C38,"") -> 0.0063011972 | G38: =IFERROR(E38/D38,"") -> 0.99968701 | H38: =IF(LEN(A38)=3,"是",IF(B38<>"",IF(SUM(C38:E38)<>0,"是","否"),"是")) -> 是 | I38: =IF(LEN(A38)=3,"类",IF(LEN(A38)=5,"款","项")) -> 项
A39: 2010402 | B39: 一般行政管理事务 | C39: ='[2]2'!E39 -> 4 | D39: 5 | E39: 117 | F39: =IFERROR((E39-C39)/C39,"") -> 28.25 | G39: =IFERROR(E39/D39,"") -> 23.4 | H39: =IF(LEN(A39)=3,"是",IF(B39<>"",IF(SUM(C39:E39)<>0,"是","否"),"是")) -> 是 | I39: =IF(LEN(A39)=3,"类",IF(LEN(A39)=5,"款","项")) -> 项
A40: 2010403 | B40: 机关服务 | C40: ='[2]2'!E40 -> 0 | E40: 0 | F40: =IFERROR((E40-C40)/C40,"") | G40: =IFERROR(E40/D40,"") | H40: =IF(LEN(A40)=3,"是",IF(B40<>"",IF(SUM(C40:E40)<>0,"是","否"),"是")) -> 否 | I40: =IF(LEN(A40)=3,"类",IF(LEN(A40)=5,"款","项")) -> 项
...

Sheet 03-1
B1: 2025年市本级一般公共预算收支情况表
B2: 表三 | H2: 单位：万元
A3: 科目编码 | B3: 项目 | C3: 2024年决算数 | D3: 2025年 | G3: 比较
D4: 预算数 | E4: 调整预算数 | F4: 执行数 | G4: 比2024年决算数增长% | H4: 完成2025年预算数的% | I4: 打印
A5: 101 | B5: 一、税收收入 | C5: =SUM(C6:C20) -> 77130 | D5: =SUM(D6:D20) -> 89559 | E5: =SUM(E6:E20) -> 89559 | F5: =SUM(F6:F20) -> 85531 | G5: =IFERROR((F5-C5)/C5,"") -> 0.10892001 | H5: =IFERROR(F5/D5,"") -> 0.95502406 | I5: =IF(LEN(A5)=3,"是",IF(B5<>"",IF(SUM(C5:F5)<>0,"是","否"),"是")) -> 是
A6: 10101 | B6: 增值税 | C6: 56284 | D6: 58634 | E6: 58634 | F6: 55637 | G6: =IFERROR((F6-C6)/C6,"") -> -0.011495274 | H6: =IFERROR(F6/D6,"") -> 0.94888631 | I6: =IF(LEN(A6)=3,"是",IF(B6<>"",IF(SUM(C6:F6)<>0,"是","否"),"是")) -> 是
A7: 10104 | B7: 企业所得税 | C7: 8678 | D7: 9614 | E7: 9614 | F7: 6961 | G7: =IFERROR((F7-C7)/C7,"") -> -0.19785665 | H7: =IFERROR(F7/D7,"") -> 0.72404826 | I7: =IF(LEN(A7)=3,"是",IF(B7<>"",IF(SUM(C7:F7)<>0,"是","否"),"是")) -> 是
A8: 10106 | B8: 个人所得税 | C8: 1317 | D8: 1447 | E8: 1447 | F8: 1378 | G8: =IFERROR((F8-C8)/C8,"") -> 0.046317388 | H8: =IFERROR(F8/D8,"") -> 0.95231513 | I8: =IF(LEN(A8)=3,"是",IF(B8<>"",IF(SUM(C8:F8)<>0,"是","否"),"是")) -> 是
A9: 10107 | B9: 资源税 | C9: 0 | D9: 8572 | E9: 8572 | F9: 7217 | G9: =IFERROR((F9-C9)/C9,"") | H9: =IFERROR(F9/D9,"") -> 0.8419272 | I9: =IF(LEN(A9)=3,"是",IF(B9<>"",IF(SUM(C9:F9)<>0,"是","否"),"是")) -> 是
A10: 10109 | B10: 城市维护建设税 | C10: 3520 | D10: 3839 | E10: 3839 | F10: 3203 | G10: =IFERROR((F10-C10)/C10,"") -> -0.090056818 | H10: =IFERROR(F10/D10,"") -> 0.83433186 | I10: =IF(LEN(A10)=3,"是",IF(B10<>"",IF(SUM(C10:F10)<>0,"是","否"),"是")) -> 是
A11: 10110 | B11: 房产税 | C11: 53 | D11: 53 | E11: 53 | F11: 53 | G11: =IFERROR((F11-C11)/C11,"") -> 0 | H11: =IFERROR(F11/D11,"") -> 1 | I11: =IF(LEN(A11)=3,"是",IF(B11<>"",IF(SUM(C11:F11)<>0,"是","否"),"是")) -> 是
A12: 10111 | B12: 印花税 | C12: 67 | D12: 90 | E12: 90 | F12: 53 | G12: =IFERROR((F12-C12)/C12,"") -> -0.20895522 | H12: =IFERROR(F12/D12,"") -> 0.58888889 | I12: =IF(LEN(A12)=3,"是",IF(B12<>"",IF(SUM(C12:F12)<>0,"是","否"),"是")) -> 是
A13: 10112 | B13: 城镇土地使用税 | C13: 16 | D13: 20 | E13: 20 | F13: 16 | G13: =IFERROR((F13-C13)/C13,"") -> 0 | H13: =IFERROR(F13/D13,"") -> 0.8 | I13: =IF(LEN(A13)=3,"是",IF(B13<>"",IF(SUM(C13:F13)<>0,"是","否"),"是")) -> 是
A14: 10113 | B14: 土地增值税 | C14: 0 | E14: 0 | G14: =IFERROR((F14-C14)/C14,"") | H14: =IFERROR(F14/D14,"") | I14: =IF(LEN(A14)=3,"是",IF(B14<>"",IF(SUM(C14:F14)<>0,"是","否"),"是")) -> 否
A15: 10114 | B15: 车船税 | C15: 0 | E15: 0 | G15: =IFERROR((F15-C15)/C15,"") | H15: =IFERROR(F15/D15,"") | I15: =IF(LEN(A15)=3,"是",IF(B15<>"",IF(SUM(C15:F15)<>0,"是","否"),"是")) -> 否
A16: 10118 | B16: 耕地占用税 | C16: 7110 | D16: 7290 | E16: 7290 | F16: 10962 | G16: =IFERROR((F16-C16)/C16,"") -> 0.54177215 | H16: =IFERROR(F16/D16,"") -> 1.5037037 | I16: =IF(LEN(A16)=3,"是",IF(B16<>"",IF(SUM(C16:F16)<>0,"是","否"),"是")) -> 是
A17: 10119 | B17: 契税 | C17: 73 | E17: 0 | G17: =IFERROR((F17-C17)/C17,"") -> -1 | H17: =IFERROR(F17/D17,"") | I17: =IF(LEN(A17)=3,"是",IF(B17<>"",IF(SUM(C17:F17)<>0,"是","否"),"是")) -> 是
A18: 10120 | B18: 烟叶税 | C18: 0 | E18: 0 | G18: =IFERROR((F18-C18)/C18,"") | H18: =IFERROR(F18/D18,"") | I18: =IF(LEN(A18)=3,"是",IF(B18<>"",IF(SUM(C18:F18)<>0,"是","否"),"是")) -> 否
A19: 10121 | B19: 环境保护税 | C19: 0 | E19: 0 | G19: =IFERROR((F19-C19)/C19,"") | H19: =IFERROR(F19/D19,"") | I19: =IF(LEN(A19)=3,"是",IF(B19<>"",IF(SUM(C19:F19)<>0,"是","否"),"是")) -> 否
A20: 10199 | B20: 其他税收收入 | C20: 12 | E20: 0 | F20: 51 | G20: =IFERROR((F20-C20)/C20,"") -> 3.25 | H20: =IFERROR(F20/D20,"") | I20: =IF(LEN(A20)=3,"是",IF(B20<>"",IF(SUM(C20:F20)<>0,"是","否"),"是")) -> 是
A21: 103 | B21: 二、非税收入 | C21: =SUM(C22:C29) -> 193211 | D21: =SUM(D22:D29) -> 194299 | E21: =SUM(E22:E29) -> 194299 | F21: =SUM(F22:F29) -> 151528 | G21: =IFERROR((F21-C21)/C21,"") -> -0.21573823 | H21: =IFERROR(F21/D21,"") -> 0.7798702 | I21: =IF(LEN(A21)=3,"是",IF(B21<>"",IF(SUM(C21:F21)<>0,"是","否"),"是")) -> 是
A22: 10302 | B22: 专项收入 | C22: 5626 | D22: 5322 | E22: 5322 | F22: 4127 | G22: =IFERROR((F22-C22)/C22,"") -> -0.26644152 | H22: =IFERROR(F22/D22,"") -> 0.77546035 | I22: =IF(LEN(A22)=3,"是",IF(B22<>"",IF(SUM(C22:F22)<>0,"是","否"),"是")) -> 是
A23: 10304 | B23: 行政事业性收费收入 | C23: 30028 | D23: 42479 | E23: 42479 | F23: 15810 | G23: =IFERROR((F23-C23)/C23,"") -> -0.47349141 | H23: =IFERROR(F23/D23,"") -> 0.3721839 | I23: =IF(LEN(A23)=3,"是",IF(B23<>"",IF(SUM(C23:F23)<>0,"是","否"),"是")) -> 是
A24: 10305 | B24: 罚没收入 | C24: 10141 | D24: 7820 | E24: 7820 | F24: 6119 | G24: =IFERROR((F24-C24)/C24,"") -> -0.39660783 | H24: =IFERROR(F24/D24,"") -> 0.78248082 | I24: =IF(LEN(A24)=3,"是",IF(B24<>"",IF(SUM(C24:F24)<>0,"是","否"),"是")) -> 是
A25: 10306 | B25: 国有资本经营收入 | C25: 0 | G25: =IFERROR((F25-C25)/C25,"") | H25: =IFERROR(F25/D25,"") | I25: =IF(LEN(A25)=3,"是",IF(B25<>"",IF(SUM(C25:F25)<>0,"是","否"),"是")) -> 否
A26: 10307 | B26: 国有资源（资产）有偿使用收入 | C26: 140768 | D26: 131528 | E26: 131528 | F26: 117392 | G26: =IFERROR((F26-C26)/C26,"") -> -0.16606047 | H26: =IFERROR(F26/D26,"") -> 0.89252479 | I26: =IF(LEN(A26)=3,"是",IF(B26<>"",IF(SUM(C26:F26)<>0,"是","否"),"是")) -> 是
A27: 10308 | B27: 捐赠收入 | C27: 0 | G27: =IFERROR((F27-C27)/C27,"") | H27: =IFERROR(F27/D27,"") | I27: =IF(LEN(A27)=3,"是",IF(B27<>"",IF(SUM(C27:F27)<>0,"是","否"),"是")) -> 否
A28: 10309 | B28: 政府住房基金收入 | C28: 6648 | D28: 7150 | E28: 7150 | F28: 8071 | G28: =IFERROR((F28-C28)/C28,"") -> 0.21404934 | H28: =IFERROR(F28/D28,"") -> 1.1288112 | I28: =IF(LEN(A28)=3,"是",IF(B28<>"",IF(SUM(C28:F28)<>0,"是","否"),"是")) -> 是
A29: 10399 | B29: 其他收入 | C29: 0 | F29: 9 | G29: =IFERROR((F29-C29)/C29,"") | H29: =IFERROR(F29/D29,"") | I29: =IF(LEN(A29)=3,"是",IF(B29<>"",IF(SUM(C29:F29)<>0,"是","否"),"是")) -> 是
G30: =IFERROR((F30-C30)/C30,"") | H30: =IFERROR(F30/D30,"") | I30: =IF(LEN(A30)=3,"是",IF(B30<>"",IF(SUM(C30:F30)<>0,"是","否"),"是")) -> 是
B31: 市本级一般公共预算收入 | C31: =SUM(C5,C21) -> 270341 | D31: =SUM(D5,D21) -> 283858 | E31: =SUM(E5,E21) -> 283858 | F31: =SUM(F5,F21) -> 237059 | G31: =IFERROR((F31-C31)/C31,"") -> -0.12311118 | H31: =IFERROR(F31/D31,"") -> 0.83513235 | I31: =IF(LEN(A31)=3,"是",IF(B31<>"",IF(SUM(C31:F31)<>0,"是","否"),"是")) -> 是
A32: 105 | B32: 地方政府一般债务收入 | C32: 180780 | D32: 192645 | E32: 242842 | F32: 237945 | G32: =IFERROR((F32-C32)/C32,"") -> 0.31621308 | H32: =IFERROR(F32/D32,"") -> 1.2351476 | I32: =IF(LEN(A32)=3,"是",IF(B32<>"",IF(SUM(C32:F32)<>0,"是","否"),"是")) -> 是
A33: 110 | B33: 转移性收入 | C33: =SUM(C34:C41) -> 1287032 | D33: =SUM(D34:D41) -> 1311102 | E33: =SUM(E34:E41) -> 1291454 | F33: =SUM(F34:F41) -> 1247877 | G33: =IFERROR((F33-C33)/C33,"") -> -0.030422709 | H33: =IFERROR(F33/D33,"") -> 0.95177721 | I33: =IF(LEN(A33)=3,"是",IF(B33<>"",IF(SUM(C33:F33)<>0,"是","否"),"是")) -> 是
A34: 11001 | B34: 返还性收入 | C34: 41410 | D34: 40300 | E34: 40300 | F34: 44029 | G34: =IFERROR((F34-C34)/C34,"") -> 0.063245593 | H34: =IFERROR(F34/D34,"") -> 1.092531 | I34: =IF(LEN(A34)=3,"是",IF(B34<>"",IF(SUM(C34:F34)<>0,"是","否"),"是")) -> 是
B35: 一般性转移支付收入 | C35: 917106 | D35: 912417 | E35: 912417 | F35: 997380 | G35: =IFERROR((F35-C35)/C35,"") -> 0.087529686 | H35: =IFERROR(F35/D35,"") -> 1.0931186 | I35: =IF(LEN(A35)=3,"是",IF(B35<>"",IF(SUM(C35:F35)<>0,"是","否"),"是")) -> 是
B36: 专项转移支付收入 | C36: 264430 | D36: 264427 | E36: 264427 | F36: 144850 | G36: =IFERROR((F36-C36)/C36,"") -> -0.45221798 | H36: =IFERROR(F36/D36,"") -> 0.54778824 | I36: =IF(LEN(A36)=3,"是",IF(B36<>"",IF(SUM(C36:F36)<>0,"是","否"),"是")) -> 是
A37: 11006 | B37: 上解收入 | C37: 33536 | D37: 34056 | E37: 34056 | F37: 34316 | G37: =IFERROR((F37-C37)/C37,"") -> 0.023258588 | H37: =IFERROR(F37/D37,"") -> 1.0076345 | I37: =IF(LEN(A37)=3,"是",IF(B37<>"",IF(SUM(C37:F37)<>0,"是","否"),"是")) -> 是
A38: 11008 | B38: 上年结余收入 | C38: 13535 | D38: 14902 | E38: 14902 | F38: 15483 | G38: =IFERROR((F38-C38)/C38,"") -> 0.14392316 | H38: =IFERROR(F38/D38,"") -> 1.0389881 | I38: =IF(LEN(A38)=3,"是",IF(B38<>"",IF(SUM(C38:F38)<>0,"是","否"),"是")) -> 是
A39: 11009 | B39: 调入资金 | C39: 17015 | D39: 45000 | E39: 25352 | F39: 11819 | G39: =IFERROR((F39-C39)/C39,"") -> -0.30537761 | H39: =IFERROR(F39/D39,"") -> 0.26264444 | I39: =IF(LEN(A39)=3,"是",IF(B39<>"",IF(SUM(C39:F39)<>0,"是","否"),"是")) -> 是
A40: 11015 | B40: 动用预算稳定调节基金 | C40: 0 | G40: =IFERROR((F40-C40)/C40,"") | H40: =IFERROR(F40/D40,"") | I40: =IF(LEN(A40)=3,"是",IF(B40<>"",IF(SUM(C40:F40)<>0,"是","否"),"是")) -> 否
...

Sheet 03-2
B1: 2025年市本级一般公共预算收支情况表
B2: 表三 | H2: 单位：万元
A3: 科目编码 | B3: 项目 | C3: 2024年决算数 | D3: 2025年 | G3: 比较
D4: 预算数 | E4: 调整预算数 | F4: 执行数 | G4: 比2024年决算数增长% | H4: 完成2025年预算数的% | I4: 打印
A5: 201 | B5: 一、一般公共服务 | C5: 39616 | D5: 44036 | E5: 44036 | F5: ='04'!F5 -> 38632 | G5: =IFERROR((F5-C5)/C5,"") -> -0.024838449 | H5: =IFERROR(F5/D5,"") -> 0.87728222 | I5: =IF(LEN(A5)=3,"是",IF(B5<>"",IF(SUM(C5:F5)<>0,"是","否"),"是")) -> 是
A6: 202 | B6: 二、外交支出 | C6: 0 | E6: 0 | F6: ='04'!F253 -> 0 | G6: =IFERROR((F6-C6)/C6,"") | H6: =IFERROR(F6/D6,"") | I6: =IF(LEN(A6)=3,"是",IF(B6<>"",IF(SUM(C6:F6)<>0,"是","否"),"是")) -> 是
A7: 203 | B7: 三、国防支出 | C7: 770 | D7: 781 | E7: 781 | F7: ='04'!F293 -> 1279 | G7: =IFERROR((F7-C7)/C7,"") -> 0.66103896 | H7: =IFERROR(F7/D7,"") -> 1.637644 | I7: =IF(LEN(A7)=3,"是",IF(B7<>"",IF(SUM(C7:F7)<>0,"是","否"),"是")) -> 是
A8: 204 | B8: 四、公共安全支出 | C8: 18147 | D8: 18644 | E8: 18597 | F8: ='04'!F312 -> 22295 | G8: =IFERROR((F8-C8)/C8,"") -> 0.22857773 | H8: =IFERROR(F8/D8,"") -> 1.1958271 | I8: =IF(LEN(A8)=3,"是",IF(B8<>"",IF(SUM(C8:F8)<>0,"是","否"),"是")) -> 是
A9: 205 | B9: 五、教育支出 | C9: 27952 | D9: 29431 | E9: 30309 | F9: ='04'!F402 -> 38236 | G9: =IFERROR((F9-C9)/C9,"") -> 0.36791643 | H9: =IFERROR(F9/D9,"") -> 1.2991743 | I9: =IF(LEN(A9)=3,"是",IF(B9<>"",IF(SUM(C9:F9)<>0,"是","否"),"是")) -> 是
A10: 206 | B10: 六、科学技术支出 | C10: 2477 | D10: 2553 | E10: 2553 | F10: ='04'!F454 -> 3289 | G10: =IFERROR((F10-C10)/C10,"") -> 0.32781591 | H10: =IFERROR(F10/D10,"") -> 1.2882883 | I10: =IF(LEN(A10)=3,"是",IF(B10<>"",IF(SUM(C10:F10)<>0,"是","否"),"是")) -> 是
A11: 207 | B11: 七、文化旅游体育与传媒支出 | C11: 12275 | D11: 12540 | E11: 12638 | F11: ='04'!F510 -> 11167 | G11: =IFERROR((F11-C11)/C11,"") -> -0.090264766 | H11: =IFERROR(F11/D11,"") -> 0.89051037 | I11: =IF(LEN(A11)=3,"是",IF(B11<>"",IF(SUM(C11:F11)<>0,"是","否"),"是")) -> 是
A12: 208 | B12: 八、社会保障和就业支出 | C12: 59198 | D12: 61422 | E12: 61422 | F12: ='04'!F566 -> 66109 | G12: =IFERROR((F12-C12)/C12,"") -> 0.11674381 | H12: =IFERROR(F12/D12,"") -> 1.0763082 | I12: =IF(LEN(A12)=3,"是",IF(B12<>"",IF(SUM(C12:F12)<>0,"是","否"),"是")) -> 是
A13: 210 | B13: 九、卫生健康支出 | C13: 99631 | D13: 102400 | E13: 102400 | F13: ='04'!F695 -> 102305 | G13: =IFERROR((F13-C13)/C13,"") -> 0.026839036 | H13: =IFERROR(F13/D13,"") -> 0.99907227 | I13: =IF(LEN(A13)=3,"是",IF(B13<>"",IF(SUM(C13:F13)<>0,"是","否"),"是")) -> 是
A14: 211 | B14: 十、节能环保支出 | C14: 59344 | D14: 60711 | E14: 55026 | F14: ='04'!F778 -> 63120 | G14: =IFERROR((F14-C14)/C14,"") -> 0.063629011 | H14: =IFERROR(F14/D14,"") -> 1.0396798 | I14: =IF(LEN(A14)=3,"是",IF(B14<>"",IF(SUM(C14:F14)<>0,"是","否"),"是")) -> 是
A15: 212 | B15: 十一、城乡社区支出 | C15: 14200 | D15: 13722 | E15: 13121 | F15: ='04'!F850 -> 17917 | G15: =IFERROR((F15-C15)/C15,"") -> 0.26176056 | H15: =IFERROR(F15/D15,"") -> 1.3057135 | I15: =IF(LEN(A15)=3,"是",IF(B15<>"",IF(SUM(C15:F15)<>0,"是","否"),"是")) -> 是
A16: 213 | B16: 十二、农林水支出 | C16: 86730 | D16: 82615 | E16: 82358 | F16: ='04'!F873 -> 17832 | G16: =IFERROR((F16-C16)/C16,"") -> -0.7943964 | H16: =IFERROR(F16/D16,"") -> 0.21584458 | I16: =IF(LEN(A16)=3,"是",IF(B16<>"",IF(SUM(C16:F16)<>0,"是","否"),"是")) -> 是
A17: 214 | B17: 十三、交通运输支出 | C17: 21839 | D17: 22433 | E17: 17634 | F17: ='04'!F976 -> 28594 | G17: =IFERROR((F17-C17)/C17,"") -> 0.30930903 | H17: =IFERROR(F17/D17,"") -> 1.27464 | I17: =IF(LEN(A17)=3,"是",IF(B17<>"",IF(SUM(C17:F17)<>0,"是","否"),"是")) -> 是
A18: 215 | B18: 十四、资源勘探工业信息等支出 | C18: 73429 | D18: 68152 | E18: 79061 | F18: ='04'!F1028 -> 44782 | G18: =IFERROR((F18-C18)/C18,"") -> -0.39013196 | H18: =IFERROR(F18/D18,"") -> 0.65709003 | I18: =IF(LEN(A18)=3,"是",IF(B18<>"",IF(SUM(C18:F18)<>0,"是","否"),"是")) -> 是
A19: 216 | B19: 十五、商业服务业等支出 | C19: 283 | D19: 292 | E19: 292 | F19: ='04'!F1092 -> 1649 | G19: =IFERROR((F19-C19)/C19,"") -> 4.8268551 | H19: =IFERROR(F19/D19,"") -> 5.6472603 | I19: =IF(LEN(A19)=3,"是",IF(B19<>"",IF(SUM(C19:F19)<>0,"是","否"),"是")) -> 是
A20: 217 | B20: 十六、金融支出 | C20: 326 | D20: 321 | E20: 321 | F20: ='04'!F1112 -> 439 | G20: =IFERROR((F20-C20)/C20,"") -> 0.34662577 | H20: =IFERROR(F20/D20,"") -> 1.3676012 | I20: =IF(LEN(A20)=3,"是",IF(B20<>"",IF(SUM(C20:F20)<>0,"是","否"),"是")) -> 是
A21: 219 | B21: 十七、援助其他地区支出 | C21: 0 | E21: 0 | F21: ='04'!F1142 -> 0 | G21: =IFERROR((F21-C21)/C21,"") | H21: =IFERROR(F21/D21,"") | I21: =IF(LEN(A21)=3,"是",IF(B21<>"",IF(SUM(C21:F21)<>0,"是","否"),"是")) -> 是
A22: 220 | B22: 十八、自然资源海洋气象等支出 | C22: 3936 | D22: 4043 | E22: 4374 | F22: ='04'!F1152 -> 6051 | G22: =IFERROR((F22-C22)/C22,"") -> 0.53734756 | H22: =IFERROR(F22/D22,"") -> 1.4966609 | I22: =IF(LEN(A22)=3,"是",IF(B22<>"",IF(SUM(C22:F22)<>0,"是","否"),"是")) -> 是
A23: 221 | B23: 十九、住房保障支出 | C23: 10177 | D23: 10285 | E23: 10285 | F23: ='04'!F1197 -> 10227 | G23: =IFERROR((F23-C23)/C23,"") -> 0.0049130392 | H23: =IFERROR(F23/D23,"") -> 0.99436072 | I23: =IF(LEN(A23)=3,"是",IF(B23<>"",IF(SUM(C23:F23)<>0,"是","否"),"是")) -> 是
A24: 222 | B24: 二十、粮油物资储备支出 | C24: 1495 | D24: 1417 | E24: 1417 | F24: ='04'!F1216 -> 1326 | G24: =IFERROR((F24-C24)/C24,"") -> -0.11304348 | H24: =IFERROR(F24/D24,"") -> 0.93577982 | I24: =IF(LEN(A24)=3,"是",IF(B24<>"",IF(SUM(C24:F24)<>0,"是","否"),"是")) -> 是
A25: 224 | B25: 二十一、灾害防治及应急管理支出 | C25: 11818 | D25: 11410 | E25: 11935 | F25: ='04'!F1261 -> 4915 | G25: =IFERROR((F25-C25)/C25,"") -> -0.58410899 | H25: =IFERROR(F25/D25,"") -> 0.43076249 | I25: =IF(LEN(A25)=3,"是",IF(B25<>"",IF(SUM(C25:F25)<>0,"是","否"),"是")) -> 是
A26: 227 | B26: 二十二、预备费 | C26: 0 | D26: 5800 | E26: 5800 | F26: ='04'!F1311 -> 0 | G26: =IFERROR((F26-C26)/C26,"") | H26: =IFERROR(F26/D26,"") -> 0 | I26: =IF(LEN(A26)=3,"是",IF(B26<>"",IF(SUM(C26:F26)<>0,"是","否"),"是")) -> 是
A27: 232 | B27: 二十三、债务付息支出 | C27: 20273 | D27: 19358 | E27: 19358 | F27: ='04'!F1312 -> 19596 | G27: =IFERROR((F27-C27)/C27,"") -> -0.03339417 | H27: =IFERROR(F27/D27,"") -> 1.0122947 | I27: =IF(LEN(A27)=3,"是",IF(B27<>"",IF(SUM(C27:F27)<>0,"是","否"),"是")) -> 是
A28: 233 | B28: 二十四、债务发行费用支出 | C28: 90 | D28: 100 | E28: 100 | F28: ='04'!F1318 -> 138 | G28: =IFERROR((F28-C28)/C28,"") -> 0.53333333 | H28: =IFERROR(F28/D28,"") -> 1.38 | I28: =IF(LEN(A28)=3,"是",IF(B28<>"",IF(SUM(C28:F28)<>0,"是","否"),"是")) -> 是
A29: 229 | B29: 二十五、其他支出 | C29: 0 | E29: 0 | F29: ='04'!F1320 -> 12 | G29: =IFERROR((F29-C29)/C29,"") | H29: =IFERROR(F29/D29,"") | I29: =IF(LEN(A29)=3,"是",IF(B29<>"",IF(SUM(C29:F29)<>0,"是","否"),"是")) -> 是
G30: =IFERROR((F30-C30)/C30,"") | H30: =IFERROR(F30/D30,"") | I30: =IF(LEN(A30)=3,"是",IF(B30<>"",IF(SUM(C30:F30)<>0,"是","否"),"是")) -> 是
B31: 市本级一般公共预算支出 | C31: =SUM(C5:C29) -> 564006 | D31: =SUM(D5:D29) -> 572466 | E31: =SUM(E5:E29) -> 573818 | F31: =SUM(F5:F29) -> 499910 | G31: =IFERROR((F31-C31)/C31,"") -> -0.11364418 | H31: =IFERROR(F31/D31,"") -> 0.8732571 | I31: =IF(LEN(A31)=3,"是",IF(B31<>"",IF(SUM(C31:F31)<>0,"是","否"),"是")) -> 是
A32: 230 | B32: 转移性支出 | C32: =SUM(C33:C40) -> 1082458 | D32: =SUM(D33:D40) -> 1093289 | E32: =SUM(E33:E40) -> 1117486 | F32: =SUM(F33:F40) -> 1085140 | G32: =IFERROR((F32-C32)/C32,"") -> 0.0024776943 | H32: =IFERROR(F32/D32,"") -> 0.99254634 | I32: =IF(LEN(A32)=3,"是",IF(B32<>"",IF(SUM(C32:F32)<>0,"是","否"),"是")) -> 是
A33: 23001 | B33: 返还性支出 | C33: 23501 | D33: 23784 | E33: 23784 | F33: 25249 | G33: =IFERROR((F33-C33)/C33,"") -> 0.074379814 | H33: =IFERROR(F33/D33,"") -> 1.061596 | I33: =IF(LEN(A33)=3,"是",IF(B33<>"",IF(SUM(C33:F33)<>0,"是","否"),"是")) -> 是
B34: 一般性转移支付支出 | C34: 745563 | D34: 770227 | E34: 770227 | F34: 785932 | G34: =IFERROR((F34-C34)/C34,"") -> 0.054145659 | H34: =IFERROR(F34/D34,"") -> 1.0203901 | I34: =IF(LEN(A34)=3,"是",IF(B34<>"",IF(SUM(C34:F34)<>0,"是","否"),"是")) -> 是
B35: 专项转移支付支出 | C35: 184676 | D35: 182414 | E35: 182414 | F35: 136446 | G35: =IFERROR((F35-C35)/C35,"") -> -0.26116009 | H35: =IFERROR(F35/D35,"") -> 0.7480018 | I35: =IF(LEN(A35)=3,"是",IF(B35<>"",IF(SUM(C35:F35)<>0,"是","否"),"是")) -> 是
A36: 23006 | B36: 上解支出 | C36: 33648 | D36: 33869 | E36: 33869 | F36: 35218 | G36: =IFERROR((F36-C36)/C36,"") -> 0.046659534 | H36: =IFERROR(F36/D36,"") -> 1.0398299 | I36: =IF(LEN(A36)=3,"是",IF(B36<>"",IF(SUM(C36:F36)<>0,"是","否"),"是")) -> 是
A37: 23008 | B37: 调出资金 | C37: 0 | G37: =IFERROR((F37-C37)/C37,"") | H37: =IFERROR(F37/D37,"") | I37: =IF(LEN(A37)=3,"是",IF(B37<>"",IF(SUM(C37:F37)<>0,"是","否"),"是")) -> 否
A38: 2301101 | B38: 地方政府一般债务转贷支出 | C38: 95070 | D38: 82995 | E38: 107192 | F38: 102295 | G38: =IFERROR((F38-C38)/C38,"") -> 0.075996634 | H38: =IFERROR(F38/D38,"") -> 1.2325441 | I38: =IF(LEN(A38)=3,"是",IF(B38<>"",IF(SUM(C38:F38)<>0,"是","否"),"是")) -> 是
A39: 23015 | B39: 安排预算稳定调节基金 | C39: 0 | G39: =IFERROR((F39-C39)/C39,"") | H39: =IFERROR(F39/D39,"") | I39: =IF(LEN(A39)=3,"是",IF(B39<>"",IF(SUM(C39:F39)<>0,"是","否"),"是")) -> 否
A40: 23016 | B40: 补充预算周转金 | C40: 0 | G40: =IFERROR((F40-C40)/C40,"") | H40: =IFERROR(F40/D40,"") | I40: =IF(LEN(A40)=3,"是",IF(B40<>"",IF(SUM(C40:F40)<>0,"是","否"),"是")) -> 否
...

Sheet 04
B1: 2025年市本级一般公共预算支出执行情况表
B2: 表四 | H2: 单位：万元
A3: 科目编码 | B3: 项目 | C3: 2024年决算数 | D3: 2025年 | G3: 比较
D4: 预算数 | E4: 调整预算数 | F4: 执行数 | G4: 比2024年决算数增长% | H4: 完成2025年预算数的% | I4: 打印 | J4: 类-款-项
A5: 201 | B5: 一、一般公共服务支出 | C5: 39616 | D5: =D6+D18+D27+D37+D48+D59+D70+D78+D87+D100+D109+D120+D132+D139+D147+D153+D160+D167+D174+D181+D188+D196+D202+D208+D215+D230+D237+D250 -> 44036 | E5: =E6+E18+E27+E37+E48+E59+E70+E78+E87+E100+E109+E120+E132+E139+E147+E153+E160+E167+E174+E181+E188+E196+E202+E208+E215+E230+E237+E250 -> 44036 | F5: =F6+F18+F27+F37+F48+F59+F70+F78+F87+F100+F109+F120+F132+F139+F147+F153+F160+F167+F174+F181+F188+F196+F202+F208+F215+F230+F237+F250 -> 38632 | G5: =IFERROR((F5-C5)/C5,"") -> -0.024838449 | H5: =IFERROR(F5/D5,"") -> 0.87728222 | I5: =IF(LEN(A5)=3,"是",IF(B5<>"",IF(SUM(C5:F5)<>0,"是","否"),"是")) -> 是 | J5: =IF(LEN(A5)=3,"类",IF(LEN(A5)=5,"款","项")) -> 类
A6: 20101 | B6: 人大事务 | C6: 1685 | D6: =SUM(D7:D17) -> 1847 | E6: =SUM(E7:E17) -> 1847 | F6: =SUM(F7:F17) -> 1558 | G6: =IFERROR((F6-C6)/C6,"") -> -0.07537092 | H6: =IFERROR(F6/D6,"") -> 0.84353005 | I6: =IF(LEN(A6)=3,"是",IF(B6<>"",IF(SUM(C6:F6)<>0,"是","否"),"是")) -> 是 | J6: =IF(LEN(A6)=3,"类",IF(LEN(A6)=5,"款","项")) -> 款
A7: 2010101 | B7: 行政运行 | C7: 1405 | D7: 1512 | E7: 1512 | F7: 1243 | G7: =IFERROR((F7-C7)/C7,"") -> -0.11530249 | H7: =IFERROR(F7/D7,"") -> 0.82208995 | I7: =IF(LEN(A7)=3,"是",IF(B7<>"",IF(SUM(C7:F7)<>0,"是","否"),"是")) -> 是 | J7: =IF(LEN(A7)=3,"类",IF(LEN(A7)=5,"款","项")) -> 项
A8: 2010102 | B8: 一般行政管理事务 | C8: 82 | D8: 86 | E8: 86 | F8: 42 | G8: =IFERROR((F8-C8)/C8,"") -> -0.48780488 | H8: =IFERROR(F8/D8,"") -> 0.48837209 | I8: =IF(LEN(A8)=3,"是",IF(B8<>"",IF(SUM(C8:F8)<>0,"是","否"),"是")) -> 是 | J8: =IF(LEN(A8)=3,"类",IF(LEN(A8)=5,"款","项")) -> 项
A9: 2010103 | B9: 机关服务 | C9: 57 | D9: 60 | E9: 60 | F9: 54 | G9: =IFERROR((F9-C9)/C9,"") -> -0.052631579 | H9: =IFERROR(F9/D9,"") -> 0.9 | I9: =IF(LEN(A9)=3,"是",IF(B9<>"",IF(SUM(C9:F9)<>0,"是","否"),"是")) -> 是 | J9: =IF(LEN(A9)=3,"类",IF(LEN(A9)=5,"款","项")) -> 项
A10: 2010104 | B10: 人大会议 | C10: 97 | D10: 120 | E10: 120 | F10: 99 | G10: =IFERROR((F10-C10)/C10,"") -> 0.020618557 | H10: =IFERROR(F10/D10,"") -> 0.825 | I10: =IF(LEN(A10)=3,"是",IF(B10<>"",IF(SUM(C10:F10)<>0,"是","否"),"是")) -> 是 | J10: =IF(LEN(A10)=3,"类",IF(LEN(A10)=5,"款","项")) -> 项
A11: 2010105 | B11: 人大立法 | C11: 0 | D11: 0 | E11: 0 | F11: 0 | G11: =IFERROR((F11-C11)/C11,"") | H11: =IFERROR(F11/D11,"") | I11: =IF(LEN(A11)=3,"是",IF(B11<>"",IF(SUM(C11:F11)<>0,"是","否"),"是")) -> 否 | J11: =IF(LEN(A11)=3,"类",IF(LEN(A11)=5,"款","项")) -> 项
A12: 2010106 | B12: 人大监督 | C12: 0 | D12: 0 | E12: 0 | F12: 0 | G12: =IFERROR((F12-C12)/C12,"") | H12: =IFERROR(F12/D12,"") | I12: =IF(LEN(A12)=3,"是",IF(B12<>"",IF(SUM(C12:F12)<>0,"是","否"),"是")) -> 否 | J12: =IF(LEN(A12)=3,"类",IF(LEN(A12)=5,"款","项")) -> 项
A13: 2010107 | B13: 人大代表履职能力提升 | C13: 9 | D13: 28 | E13: 28 | F13: 26 | G13: =IFERROR((F13-C13)/C13,"") -> 1.8888889 | H13: =IFERROR(F13/D13,"") -> 0.92857143 | I13: =IF(LEN(A13)=3,"是",IF(B13<>"",IF(SUM(C13:F13)<>0,"是","否"),"是")) -> 是 | J13: =IF(LEN(A13)=3,"类",IF(LEN(A13)=5,"款","项")) -> 项
A14: 2010108 | B14: 代表工作 | C14: 0 | D14: 0 | E14: 0 | F14: 9 | G14: =IFERROR((F14-C14)/C14,"") | H14: =IFERROR(F14/D14,"") | I14: =IF(LEN(A14)=3,"是",IF(B14<>"",IF(SUM(C14:F14)<>0,"是","否"),"是")) -> 是 | J14: =IF(LEN(A14)=3,"类",IF(LEN(A14)=5,"款","项")) -> 项
A15: 2010109 | B15: 人大信访工作 | C15: 0 | D15: 0 | E15: 0 | F15: 0 | G15: =IFERROR((F15-C15)/C15,"") | H15: =IFERROR(F15/D15,"") | I15: =IF(LEN(A15)=3,"是",IF(B15<>"",IF(SUM(C15:F15)<>0,"是","否"),"是")) -> 否 | J15: =IF(LEN(A15)=3,"类",IF(LEN(A15)=5,"款","项")) -> 项
A16: 2010150 | B16: 事业运行 | C16: 0 | D16: 0 | E16: 0 | F16: 0 | G16: =IFERROR((F16-C16)/C16,"") | H16: =IFERROR(F16/D16,"") | I16: =IF(LEN(A16)=3,"是",IF(B16<>"",IF(SUM(C16:F16)<>0,"是","否"),"是")) -> 否 | J16: =IF(LEN(A16)=3,"类",IF(LEN(A16)=5,"款","项")) -> 项
A17: 2010199 | B17: 其他人大事务支出 | C17: 35 | D17: 41 | E17: 41 | F17: 85 | G17: =IFERROR((F17-C17)/C17,"") -> 1.4285714 | H17: =IFERROR(F17/D17,"") -> 2.0731707 | I17: =IF(LEN(A17)=3,"是",IF(B17<>"",IF(SUM(C17:F17)<>0,"是","否"),"是")) -> 是 | J17: =IF(LEN(A17)=3,"类",IF(LEN(A17)=5,"款","项")) -> 项
A18: 20102 | B18: 政协事务 | C18: 1481 | D18: =SUM(D19:D26) -> 1598 | E18: =SUM(E19:E26) -> 1598 | F18: =SUM(F19:F26) -> 1613 | G18: =IFERROR((F18-C18)/C18,"") -> 0.089128967 | H18: =IFERROR(F18/D18,"") -> 1.0093867 | I18: =IF(LEN(A18)=3,"是",IF(B18<>"",IF(SUM(C18:F18)<>0,"是","否"),"是")) -> 是 | J18: =IF(LEN(A18)=3,"类",IF(LEN(A18)=5,"款","项")) -> 款
A19: 2010201 | B19: 行政运行 | C19: 1305 | D19: 1403 | E19: 1403 | F19: 1529 | G19: =IFERROR((F19-C19)/C19,"") -> 0.17164751 | H19: =IFERROR(F19/D19,"") -> 1.0898076 | I19: =IF(LEN(A19)=3,"是",IF(B19<>"",IF(SUM(C19:F19)<>0,"是","否"),"是")) -> 是 | J19: =IF(LEN(A19)=3,"类",IF(LEN(A19)=5,"款","项")) -> 项
A20: 2010202 | B20: 一般行政管理事务 | C20: 47 | D20: 51 | E20: 51 | F20: 21 | G20: =IFERROR((F20-C20)/C20,"") -> -0.55319149 | H20: =IFERROR(F20/D20,"") -> 0.41176471 | I20: =IF(LEN(A20)=3,"是",IF(B20<>"",IF(SUM(C20:F20)<>0,"是","否"),"是")) -> 是 | J20: =IF(LEN(A20)=3,"类",IF(LEN(A20)=5,"款","项")) -> 项
A21: 2010203 | B21: 机关服务 | C21: 0 | D21: 0 | E21: 0 | F21: 0 | G21: =IFERROR((F21-C21)/C21,"") | H21: =IFERROR(F21/D21,"") | I21: =IF(LEN(A21)=3,"是",IF(B21<>"",IF(SUM(C21:F21)<>0,"是","否"),"是")) -> 否 | J21: =IF(LEN(A21)=3,"类",IF(LEN(A21)=5,"款","项")) -> 项
A22: 2010204 | B22: 政协会议 | C22: 75 | D22: 81 | E22: 81 | F22: 0 | G22: =IFERROR((F22-C22)/C22,"") -> -1 | H22: =IFERROR(F22/D22,"") -> 0 | I22: =IF(LEN(A22)=3,"是",IF(B22<>"",IF(SUM(C22:F22)<>0,"是","否"),"是")) -> 是 | J22: =IF(LEN(A22)=3,"类",IF(LEN(A22)=5,"款","项")) -> 项
A23: 2010205 | B23: 委员视察 | C23: 0 | D23: 0 | E23: 0 | F23: 0 | G23: =IFERROR((F23-C23)/C23,"") | H23: =IFERROR(F23/D23,"") | I23: =IF(LEN(A23)=3,"是",IF(B23<>"",IF(SUM(C23:F23)<>0,"是","否"),"是")) -> 否 | J23: =IF(LEN(A23)=3,"类",IF(LEN(A23)=5,"款","项")) -> 项
A24: 2010206 | B24: 参政议政 | C24: 15 | D24: 18 | E24: 18 | F24: 11 | G24: =IFERROR((F24-C24)/C24,"") -> -0.26666667 | H24: =IFERROR(F24/D24,"") -> 0.61111111 | I24: =IF(LEN(A24)=3,"是",IF(B24<>"",IF(SUM(C24:F24)<>0,"是","否"),"是")) -> 是 | J24: =IF(LEN(A24)=3,"类",IF(LEN(A24)=5,"款","项")) -> 项
A25: 2010250 | B25: 事业运行 | C25: 0 | D25: 0 | E25: 0 | F25: 0 | G25: =IFERROR((F25-C25)/C25,"") | H25: =IFERROR(F25/D25,"") | I25: =IF(LEN(A25)=3,"是",IF(B25<>"",IF(SUM(C25:F25)<>0,"是","否"),"是")) -> 否 | J25: =IF(LEN(A25)=3,"类",IF(LEN(A25)=5,"款","项")) -> 项
A26: 2010299 | B26: 其他政协事务支出 | C26: 39 | D26: 45 | E26: 45 | F26: 52 | G26: =IFERROR((F26-C26)/C26,"") -> 0.33333333 | H26: =IFERROR(F26/D26,"") -> 1.1555556 | I26: =IF(LEN(A26)=3,"是",IF(B26<>"",IF(SUM(C26:F26)<>0,"是","否"),"是")) -> 是 | J26: =IF(LEN(A26)=3,"类",IF(LEN(A26)=5,"款","项")) -> 项
A27: 20103 | B27: 政府办公厅(室)及相关机构事务 | C27: 7638 | D27: =SUM(D28:D36) -> 8020 | E27: =SUM(E28:E36) -> 8020 | F27: =SUM(F28:F36) -> 7190 | G27: =IFERROR((F27-C27)/C27,"") -> -0.058654098 | H27: =IFERROR(F27/D27,"") -> 0.89650873 | I27: =IF(LEN(A27)=3,"是",IF(B27<>"",IF(SUM(C27:F27)<>0,"是","否"),"是")) -> 是 | J27: =IF(LEN(A27)=3,"类",IF(LEN(A27)=5,"款","项")) -> 款
A28: 2010301 | B28: 行政运行 | C28: 3457 | D28: 3568 | E28: 3568 | F28: 3412 | G28: =IFERROR((F28-C28)/C28,"") -> -0.013017067 | H28: =IFERROR(F28/D28,"") -> 0.95627803 | I28: =IF(LEN(A28)=3,"是",IF(B28<>"",IF(SUM(C28:F28)<>0,"是","否"),"是")) -> 是 | J28: =IF(LEN(A28)=3,"类",IF(LEN(A28)=5,"款","项")) -> 项
